*** Starting uWSGI 2.0.18 (64bit) on [Wed Oct 23 07:58:46 2019] ***
compiled with version: 7.4.0 on 23 October 2019 07:53:54
os: Linux-4.15.0-1051-aws #53-Ubuntu SMP Wed Sep 18 13:35:53 UTC 2019
nodename: ip-172-31-33-157
machine: x86_64
clock source: unix
detected number of CPU cores: 1
current working directory: /home/ubuntu/RockJiggu
writing pidfile to /tmp/project-master.pid
detected binary path: /home/ubuntu/RockJiggu/venv/bin/uwsgi
!!! no internal routing support, rebuild with pcre support !!!
chdir() to /home/ubuntu/RockJiggu
your processes number limit is 3841
your memory page size is 4096 bytes
detected max file descriptor number: 1024
lock engine: pthread robust mutexes
thunder lock: disabled (you can enable it with --thunder-lock)
uwsgi socket 0 bound to UNIX address /home/ubuntu/RockJiggu/uwsgi.sock fd 3
Python version: 3.6.8 (default, Oct  7 2019, 12:59:55)  [GCC 8.3.0]
Set PythonHome to /home/ubuntu/RockJiggu/venv
*** Python threads support is disabled. You can enable it with --enable-threads ***
Python main interpreter initialized at 0x5632eded6690
your server socket listen backlog is limited to 100 connections
your mercy for graceful operations on workers is 60 seconds
mapped 145808 bytes (142 KB) for 1 cores
*** Operational MODE: single process ***
WSGI app 0 (mountpoint='') ready in 0 seconds on interpreter 0x5632eded6690 pid: 19554 (default app)
*** uWSGI is running in multiple interpreter mode ***
spawned uWSGI master process (pid: 19554)
spawned uWSGI worker 1 (pid: 19556, cores: 1)
Internal Server Error: /
Traceback (most recent call last):
  File "/home/ubuntu/RockJiggu/venv/lib/python3.6/site-packages/django/core/handlers/exception.py", line 34, in inner
    response = get_response(request)
  File "/home/ubuntu/RockJiggu/venv/lib/python3.6/site-packages/django/core/handlers/base.py", line 100, in _get_response
    resolver_match = resolver.resolve(request.path_info)
  File "/home/ubuntu/RockJiggu/venv/lib/python3.6/site-packages/django/urls/resolvers.py", line 536, in resolve
    for pattern in self.url_patterns:
  File "/home/ubuntu/RockJiggu/venv/lib/python3.6/site-packages/django/utils/functional.py", line 80, in __get__
    res = instance.__dict__[self.name] = self.func(instance)
  File "/home/ubuntu/RockJiggu/venv/lib/python3.6/site-packages/django/urls/resolvers.py", line 584, in url_patterns
    patterns = getattr(self.urlconf_module, "urlpatterns", self.urlconf_module)
  File "/home/ubuntu/RockJiggu/venv/lib/python3.6/site-packages/django/utils/functional.py", line 80, in __get__
    res = instance.__dict__[self.name] = self.func(instance)
  File "/home/ubuntu/RockJiggu/venv/lib/python3.6/site-packages/django/urls/resolvers.py", line 577, in urlconf_module
    return import_module(self.urlconf_name)
  File "/home/ubuntu/RockJiggu/venv/lib/python3.6/importlib/__init__.py", line 126, in import_module
    return _bootstrap._gcd_import(name[level:], package, level)
  File "<frozen importlib._bootstrap>", line 994, in _gcd_import
  File "<frozen importlib._bootstrap>", line 971, in _find_and_load
  File "<frozen importlib._bootstrap>", line 955, in _find_and_load_unlocked
  File "<frozen importlib._bootstrap>", line 665, in _load_unlocked
  File "<frozen importlib._bootstrap_external>", line 678, in exec_module
  File "<frozen importlib._bootstrap>", line 219, in _call_with_frames_removed
  File "./RockJiggu/urls.py", line 18, in <module>
    from chatbot import urls as chatbot_url
  File "./chatbot/urls.py", line 2, in <module>
    from . import views
  File "./chatbot/views.py", line 19
    returns self_introduce()
                         ^
SyntaxError: invalid syntax
[pid: 19556|app: 0|req: 1/1] 110.13.194.132 () {40 vars in 722 bytes} [Wed Oct 23 08:06:36 2019] GET / => generated 109875 bytes in 64 msecs (HTTP/1.1 500) 4 headers in 130 bytes (2 switches on core 0)
Internal Server Error: /favicon.ico
Traceback (most recent call last):
  File "/home/ubuntu/RockJiggu/venv/lib/python3.6/site-packages/django/core/handlers/exception.py", line 34, in inner
    response = get_response(request)
  File "/home/ubuntu/RockJiggu/venv/lib/python3.6/site-packages/django/utils/deprecation.py", line 93, in __call__
    response = self.process_request(request)
  File "/home/ubuntu/RockJiggu/venv/lib/python3.6/site-packages/django/middleware/common.py", line 52, in process_request
    if self.should_redirect_with_slash(request):
  File "/home/ubuntu/RockJiggu/venv/lib/python3.6/site-packages/django/middleware/common.py", line 70, in should_redirect_with_slash
    not is_valid_path(request.path_info, urlconf) and
  File "/home/ubuntu/RockJiggu/venv/lib/python3.6/site-packages/django/urls/base.py", line 157, in is_valid_path
    resolve(path, urlconf)
  File "/home/ubuntu/RockJiggu/venv/lib/python3.6/site-packages/django/urls/base.py", line 24, in resolve
    return get_resolver(urlconf).resolve(path)
  File "/home/ubuntu/RockJiggu/venv/lib/python3.6/site-packages/django/urls/resolvers.py", line 536, in resolve
    for pattern in self.url_patterns:
  File "/home/ubuntu/RockJiggu/venv/lib/python3.6/site-packages/django/utils/functional.py", line 80, in __get__
    res = instance.__dict__[self.name] = self.func(instance)
  File "/home/ubuntu/RockJiggu/venv/lib/python3.6/site-packages/django/urls/resolvers.py", line 584, in url_patterns
    patterns = getattr(self.urlconf_module, "urlpatterns", self.urlconf_module)
  File "/home/ubuntu/RockJiggu/venv/lib/python3.6/site-packages/django/utils/functional.py", line 80, in __get__
    res = instance.__dict__[self.name] = self.func(instance)
  File "/home/ubuntu/RockJiggu/venv/lib/python3.6/site-packages/django/urls/resolvers.py", line 577, in urlconf_module
    return import_module(self.urlconf_name)
  File "/home/ubuntu/RockJiggu/venv/lib/python3.6/importlib/__init__.py", line 126, in import_module
    return _bootstrap._gcd_import(name[level:], package, level)
  File "<frozen importlib._bootstrap>", line 994, in _gcd_import
  File "<frozen importlib._bootstrap>", line 971, in _find_and_load
  File "<frozen importlib._bootstrap>", line 955, in _find_and_load_unlocked
  File "<frozen importlib._bootstrap>", line 665, in _load_unlocked
  File "<frozen importlib._bootstrap_external>", line 678, in exec_module
  File "<frozen importlib._bootstrap>", line 219, in _call_with_frames_removed
  File "./RockJiggu/urls.py", line 18, in <module>
    from chatbot import urls as chatbot_url
  File "./chatbot/urls.py", line 2, in <module>
    from . import views
  File "./chatbot/views.py", line 19
    returns self_introduce()
                         ^
SyntaxError: invalid syntax
[pid: 19556|app: 0|req: 2/2] 110.13.194.132 () {40 vars in 668 bytes} [Wed Oct 23 08:06:38 2019] GET /favicon.ico => generated 125612 bytes in 66 msecs (HTTP/1.1 500) 1 headers in 63 bytes (1 switches on core 0)
Internal Server Error: /
Traceback (most recent call last):
  File "/home/ubuntu/RockJiggu/venv/lib/python3.6/site-packages/django/core/handlers/exception.py", line 34, in inner
    response = get_response(request)
  File "/home/ubuntu/RockJiggu/venv/lib/python3.6/site-packages/django/core/handlers/base.py", line 100, in _get_response
    resolver_match = resolver.resolve(request.path_info)
  File "/home/ubuntu/RockJiggu/venv/lib/python3.6/site-packages/django/urls/resolvers.py", line 536, in resolve
    for pattern in self.url_patterns:
  File "/home/ubuntu/RockJiggu/venv/lib/python3.6/site-packages/django/utils/functional.py", line 80, in __get__
    res = instance.__dict__[self.name] = self.func(instance)
  File "/home/ubuntu/RockJiggu/venv/lib/python3.6/site-packages/django/urls/resolvers.py", line 584, in url_patterns
    patterns = getattr(self.urlconf_module, "urlpatterns", self.urlconf_module)
  File "/home/ubuntu/RockJiggu/venv/lib/python3.6/site-packages/django/utils/functional.py", line 80, in __get__
    res = instance.__dict__[self.name] = self.func(instance)
  File "/home/ubuntu/RockJiggu/venv/lib/python3.6/site-packages/django/urls/resolvers.py", line 577, in urlconf_module
    return import_module(self.urlconf_name)
  File "/home/ubuntu/RockJiggu/venv/lib/python3.6/importlib/__init__.py", line 126, in import_module
    return _bootstrap._gcd_import(name[level:], package, level)
  File "<frozen importlib._bootstrap>", line 994, in _gcd_import
  File "<frozen importlib._bootstrap>", line 971, in _find_and_load
  File "<frozen importlib._bootstrap>", line 955, in _find_and_load_unlocked
  File "<frozen importlib._bootstrap>", line 665, in _load_unlocked
  File "<frozen importlib._bootstrap_external>", line 678, in exec_module
  File "<frozen importlib._bootstrap>", line 219, in _call_with_frames_removed
  File "./RockJiggu/urls.py", line 18, in <module>
    from chatbot import urls as chatbot_url
  File "./chatbot/urls.py", line 2, in <module>
    from . import views
  File "./chatbot/views.py", line 19
    returns self_introduce()
                         ^
SyntaxError: invalid syntax
[pid: 19556|app: 0|req: 3/3] 71.6.232.4 () {34 vars in 465 bytes} [Wed Oct 23 09:32:45 2019] GET / => generated 109306 bytes in 48 msecs (HTTP/1.1 500) 4 headers in 130 bytes (2 switches on core 0)
Internal Server Error: /
Traceback (most recent call last):
  File "/home/ubuntu/RockJiggu/venv/lib/python3.6/site-packages/django/core/handlers/exception.py", line 34, in inner
    response = get_response(request)
  File "/home/ubuntu/RockJiggu/venv/lib/python3.6/site-packages/django/core/handlers/base.py", line 100, in _get_response
    resolver_match = resolver.resolve(request.path_info)
  File "/home/ubuntu/RockJiggu/venv/lib/python3.6/site-packages/django/urls/resolvers.py", line 536, in resolve
    for pattern in self.url_patterns:
  File "/home/ubuntu/RockJiggu/venv/lib/python3.6/site-packages/django/utils/functional.py", line 80, in __get__
    res = instance.__dict__[self.name] = self.func(instance)
  File "/home/ubuntu/RockJiggu/venv/lib/python3.6/site-packages/django/urls/resolvers.py", line 584, in url_patterns
    patterns = getattr(self.urlconf_module, "urlpatterns", self.urlconf_module)
  File "/home/ubuntu/RockJiggu/venv/lib/python3.6/site-packages/django/utils/functional.py", line 80, in __get__
    res = instance.__dict__[self.name] = self.func(instance)
  File "/home/ubuntu/RockJiggu/venv/lib/python3.6/site-packages/django/urls/resolvers.py", line 577, in urlconf_module
    return import_module(self.urlconf_name)
  File "/home/ubuntu/RockJiggu/venv/lib/python3.6/importlib/__init__.py", line 126, in import_module
    return _bootstrap._gcd_import(name[level:], package, level)
  File "<frozen importlib._bootstrap>", line 994, in _gcd_import
  File "<frozen importlib._bootstrap>", line 971, in _find_and_load
  File "<frozen importlib._bootstrap>", line 955, in _find_and_load_unlocked
  File "<frozen importlib._bootstrap>", line 665, in _load_unlocked
  File "<frozen importlib._bootstrap_external>", line 678, in exec_module
  File "<frozen importlib._bootstrap>", line 219, in _call_with_frames_removed
  File "./RockJiggu/urls.py", line 18, in <module>
    from chatbot import urls as chatbot_url
  File "./chatbot/urls.py", line 2, in <module>
    from . import views
  File "./chatbot/views.py", line 19
    returns self_introduce()
                         ^
SyntaxError: invalid syntax
[pid: 19556|app: 0|req: 4/4] 189.79.127.215 () {32 vars in 445 bytes} [Wed Oct 23 11:44:01 2019] GET / => generated 109188 bytes in 54 msecs (HTTP/1.1 500) 4 headers in 130 bytes (2 switches on core 0)
Invalid HTTP_HOST header: '_'. The domain name provided is not valid according to RFC 1034/1035.
Bad Request: /
[pid: 19556|app: 0|req: 5/5] 93.113.125.89 () {30 vars in 324 bytes} [Wed Oct 23 13:21:55 2019] GET / => generated 54157 bytes in 32 msecs (HTTP/1.0 400) 1 headers in 53 bytes (2 switches on core 0)
Internal Server Error: /TP/public/index.php
Traceback (most recent call last):
  File "/home/ubuntu/RockJiggu/venv/lib/python3.6/site-packages/django/core/handlers/exception.py", line 34, in inner
    response = get_response(request)
  File "/home/ubuntu/RockJiggu/venv/lib/python3.6/site-packages/django/utils/deprecation.py", line 93, in __call__
    response = self.process_request(request)
  File "/home/ubuntu/RockJiggu/venv/lib/python3.6/site-packages/django/middleware/common.py", line 52, in process_request
    if self.should_redirect_with_slash(request):
  File "/home/ubuntu/RockJiggu/venv/lib/python3.6/site-packages/django/middleware/common.py", line 70, in should_redirect_with_slash
    not is_valid_path(request.path_info, urlconf) and
  File "/home/ubuntu/RockJiggu/venv/lib/python3.6/site-packages/django/urls/base.py", line 157, in is_valid_path
    resolve(path, urlconf)
  File "/home/ubuntu/RockJiggu/venv/lib/python3.6/site-packages/django/urls/base.py", line 24, in resolve
    return get_resolver(urlconf).resolve(path)
  File "/home/ubuntu/RockJiggu/venv/lib/python3.6/site-packages/django/urls/resolvers.py", line 536, in resolve
    for pattern in self.url_patterns:
  File "/home/ubuntu/RockJiggu/venv/lib/python3.6/site-packages/django/utils/functional.py", line 80, in __get__
    res = instance.__dict__[self.name] = self.func(instance)
  File "/home/ubuntu/RockJiggu/venv/lib/python3.6/site-packages/django/urls/resolvers.py", line 584, in url_patterns
    patterns = getattr(self.urlconf_module, "urlpatterns", self.urlconf_module)
  File "/home/ubuntu/RockJiggu/venv/lib/python3.6/site-packages/django/utils/functional.py", line 80, in __get__
    res = instance.__dict__[self.name] = self.func(instance)
  File "/home/ubuntu/RockJiggu/venv/lib/python3.6/site-packages/django/urls/resolvers.py", line 577, in urlconf_module
    return import_module(self.urlconf_name)
  File "/home/ubuntu/RockJiggu/venv/lib/python3.6/importlib/__init__.py", line 126, in import_module
    return _bootstrap._gcd_import(name[level:], package, level)
  File "<frozen importlib._bootstrap>", line 994, in _gcd_import
  File "<frozen importlib._bootstrap>", line 971, in _find_and_load
  File "<frozen importlib._bootstrap>", line 955, in _find_and_load_unlocked
  File "<frozen importlib._bootstrap>", line 665, in _load_unlocked
  File "<frozen importlib._bootstrap_external>", line 678, in exec_module
  File "<frozen importlib._bootstrap>", line 219, in _call_with_frames_removed
  File "./RockJiggu/urls.py", line 18, in <module>
    from chatbot import urls as chatbot_url
  File "./chatbot/urls.py", line 2, in <module>
    from . import views
  File "./chatbot/views.py", line 19
    returns self_introduce()
                         ^
SyntaxError: invalid syntax
[pid: 19556|app: 0|req: 6/6] 120.204.202.112 () {34 vars in 483 bytes} [Wed Oct 23 14:05:38 2019] GET /TP/public/index.php => generated 125235 bytes in 56 msecs (HTTP/1.1 500) 1 headers in 63 bytes (2 switches on core 0)
Internal Server Error: /TP/index.php
Traceback (most recent call last):
  File "/home/ubuntu/RockJiggu/venv/lib/python3.6/site-packages/django/core/handlers/exception.py", line 34, in inner
    response = get_response(request)
  File "/home/ubuntu/RockJiggu/venv/lib/python3.6/site-packages/django/utils/deprecation.py", line 93, in __call__
    response = self.process_request(request)
  File "/home/ubuntu/RockJiggu/venv/lib/python3.6/site-packages/django/middleware/common.py", line 52, in process_request
    if self.should_redirect_with_slash(request):
  File "/home/ubuntu/RockJiggu/venv/lib/python3.6/site-packages/django/middleware/common.py", line 70, in should_redirect_with_slash
    not is_valid_path(request.path_info, urlconf) and
  File "/home/ubuntu/RockJiggu/venv/lib/python3.6/site-packages/django/urls/base.py", line 157, in is_valid_path
    resolve(path, urlconf)
  File "/home/ubuntu/RockJiggu/venv/lib/python3.6/site-packages/django/urls/base.py", line 24, in resolve
    return get_resolver(urlconf).resolve(path)
  File "/home/ubuntu/RockJiggu/venv/lib/python3.6/site-packages/django/urls/resolvers.py", line 536, in resolve
    for pattern in self.url_patterns:
  File "/home/ubuntu/RockJiggu/venv/lib/python3.6/site-packages/django/utils/functional.py", line 80, in __get__
    res = instance.__dict__[self.name] = self.func(instance)
  File "/home/ubuntu/RockJiggu/venv/lib/python3.6/site-packages/django/urls/resolvers.py", line 584, in url_patterns
    patterns = getattr(self.urlconf_module, "urlpatterns", self.urlconf_module)
  File "/home/ubuntu/RockJiggu/venv/lib/python3.6/site-packages/django/utils/functional.py", line 80, in __get__
    res = instance.__dict__[self.name] = self.func(instance)
  File "/home/ubuntu/RockJiggu/venv/lib/python3.6/site-packages/django/urls/resolvers.py", line 577, in urlconf_module
    return import_module(self.urlconf_name)
  File "/home/ubuntu/RockJiggu/venv/lib/python3.6/importlib/__init__.py", line 126, in import_module
    return _bootstrap._gcd_import(name[level:], package, level)
  File "<frozen importlib._bootstrap>", line 994, in _gcd_import
  File "<frozen importlib._bootstrap>", line 971, in _find_and_load
  File "<frozen importlib._bootstrap>", line 955, in _find_and_load_unlocked
  File "<frozen importlib._bootstrap>", line 665, in _load_unlocked
  File "<frozen importlib._bootstrap_external>", line 678, in exec_module
  File "<frozen importlib._bootstrap>", line 219, in _call_with_frames_removed
  File "./RockJiggu/urls.py", line 18, in <module>
    from chatbot import urls as chatbot_url
  File "./chatbot/urls.py", line 2, in <module>
    from . import views
  File "./chatbot/views.py", line 19
    returns self_introduce()
                         ^
SyntaxError: invalid syntax
[pid: 19556|app: 0|req: 7/7] 120.204.202.112 () {34 vars in 469 bytes} [Wed Oct 23 14:05:38 2019] GET /TP/index.php => generated 125116 bytes in 54 msecs (HTTP/1.1 500) 1 headers in 63 bytes (1 switches on core 0)
Internal Server Error: /thinkphp/html/public/index.php
Traceback (most recent call last):
  File "/home/ubuntu/RockJiggu/venv/lib/python3.6/site-packages/django/core/handlers/exception.py", line 34, in inner
    response = get_response(request)
  File "/home/ubuntu/RockJiggu/venv/lib/python3.6/site-packages/django/utils/deprecation.py", line 93, in __call__
    response = self.process_request(request)
  File "/home/ubuntu/RockJiggu/venv/lib/python3.6/site-packages/django/middleware/common.py", line 52, in process_request
    if self.should_redirect_with_slash(request):
  File "/home/ubuntu/RockJiggu/venv/lib/python3.6/site-packages/django/middleware/common.py", line 70, in should_redirect_with_slash
    not is_valid_path(request.path_info, urlconf) and
  File "/home/ubuntu/RockJiggu/venv/lib/python3.6/site-packages/django/urls/base.py", line 157, in is_valid_path
    resolve(path, urlconf)
  File "/home/ubuntu/RockJiggu/venv/lib/python3.6/site-packages/django/urls/base.py", line 24, in resolve
    return get_resolver(urlconf).resolve(path)
  File "/home/ubuntu/RockJiggu/venv/lib/python3.6/site-packages/django/urls/resolvers.py", line 536, in resolve
    for pattern in self.url_patterns:
  File "/home/ubuntu/RockJiggu/venv/lib/python3.6/site-packages/django/utils/functional.py", line 80, in __get__
    res = instance.__dict__[self.name] = self.func(instance)
  File "/home/ubuntu/RockJiggu/venv/lib/python3.6/site-packages/django/urls/resolvers.py", line 584, in url_patterns
    patterns = getattr(self.urlconf_module, "urlpatterns", self.urlconf_module)
  File "/home/ubuntu/RockJiggu/venv/lib/python3.6/site-packages/django/utils/functional.py", line 80, in __get__
    res = instance.__dict__[self.name] = self.func(instance)
  File "/home/ubuntu/RockJiggu/venv/lib/python3.6/site-packages/django/urls/resolvers.py", line 577, in urlconf_module
    return import_module(self.urlconf_name)
  File "/home/ubuntu/RockJiggu/venv/lib/python3.6/importlib/__init__.py", line 126, in import_module
    return _bootstrap._gcd_import(name[level:], package, level)
  File "<frozen importlib._bootstrap>", line 994, in _gcd_import
  File "<frozen importlib._bootstrap>", line 971, in _find_and_load
  File "<frozen importlib._bootstrap>", line 955, in _find_and_load_unlocked
  File "<frozen importlib._bootstrap>", line 665, in _load_unlocked
  File "<frozen importlib._bootstrap_external>", line 678, in exec_module
  File "<frozen importlib._bootstrap>", line 219, in _call_with_frames_removed
  File "./RockJiggu/urls.py", line 18, in <module>
    from chatbot import urls as chatbot_url
  File "./chatbot/urls.py", line 2, in <module>
    from . import views
  File "./chatbot/views.py", line 19
    returns self_introduce()
                         ^
SyntaxError: invalid syntax
[pid: 19556|app: 0|req: 8/8] 120.204.202.112 () {34 vars in 505 bytes} [Wed Oct 23 14:05:38 2019] GET /thinkphp/html/public/index.php => generated 125422 bytes in 55 msecs (HTTP/1.1 500) 1 headers in 63 bytes (1 switches on core 0)
Internal Server Error: /html/public/index.php
Traceback (most recent call last):
  File "/home/ubuntu/RockJiggu/venv/lib/python3.6/site-packages/django/core/handlers/exception.py", line 34, in inner
    response = get_response(request)
  File "/home/ubuntu/RockJiggu/venv/lib/python3.6/site-packages/django/utils/deprecation.py", line 93, in __call__
    response = self.process_request(request)
  File "/home/ubuntu/RockJiggu/venv/lib/python3.6/site-packages/django/middleware/common.py", line 52, in process_request
    if self.should_redirect_with_slash(request):
  File "/home/ubuntu/RockJiggu/venv/lib/python3.6/site-packages/django/middleware/common.py", line 70, in should_redirect_with_slash
    not is_valid_path(request.path_info, urlconf) and
  File "/home/ubuntu/RockJiggu/venv/lib/python3.6/site-packages/django/urls/base.py", line 157, in is_valid_path
    resolve(path, urlconf)
  File "/home/ubuntu/RockJiggu/venv/lib/python3.6/site-packages/django/urls/base.py", line 24, in resolve
    return get_resolver(urlconf).resolve(path)
  File "/home/ubuntu/RockJiggu/venv/lib/python3.6/site-packages/django/urls/resolvers.py", line 536, in resolve
    for pattern in self.url_patterns:
  File "/home/ubuntu/RockJiggu/venv/lib/python3.6/site-packages/django/utils/functional.py", line 80, in __get__
    res = instance.__dict__[self.name] = self.func(instance)
  File "/home/ubuntu/RockJiggu/venv/lib/python3.6/site-packages/django/urls/resolvers.py", line 584, in url_patterns
    patterns = getattr(self.urlconf_module, "urlpatterns", self.urlconf_module)
  File "/home/ubuntu/RockJiggu/venv/lib/python3.6/site-packages/django/utils/functional.py", line 80, in __get__
    res = instance.__dict__[self.name] = self.func(instance)
  File "/home/ubuntu/RockJiggu/venv/lib/python3.6/site-packages/django/urls/resolvers.py", line 577, in urlconf_module
    return import_module(self.urlconf_name)
  File "/home/ubuntu/RockJiggu/venv/lib/python3.6/importlib/__init__.py", line 126, in import_module
    return _bootstrap._gcd_import(name[level:], package, level)
  File "<frozen importlib._bootstrap>", line 994, in _gcd_import
  File "<frozen importlib._bootstrap>", line 971, in _find_and_load
  File "<frozen importlib._bootstrap>", line 955, in _find_and_load_unlocked
  File "<frozen importlib._bootstrap>", line 665, in _load_unlocked
  File "<frozen importlib._bootstrap_external>", line 678, in exec_module
  File "<frozen importlib._bootstrap>", line 219, in _call_with_frames_removed
  File "./RockJiggu/urls.py", line 18, in <module>
    from chatbot import urls as chatbot_url
  File "./chatbot/urls.py", line 2, in <module>
    from . import views
  File "./chatbot/views.py", line 19
    returns self_introduce()
                         ^
SyntaxError: invalid syntax
[pid: 19556|app: 0|req: 9/9] 120.204.202.112 () {34 vars in 487 bytes} [Wed Oct 23 14:05:39 2019] GET /html/public/index.php => generated 125269 bytes in 52 msecs (HTTP/1.1 500) 1 headers in 63 bytes (1 switches on core 0)
Internal Server Error: /public/index.php
Traceback (most recent call last):
  File "/home/ubuntu/RockJiggu/venv/lib/python3.6/site-packages/django/core/handlers/exception.py", line 34, in inner
    response = get_response(request)
  File "/home/ubuntu/RockJiggu/venv/lib/python3.6/site-packages/django/utils/deprecation.py", line 93, in __call__
    response = self.process_request(request)
  File "/home/ubuntu/RockJiggu/venv/lib/python3.6/site-packages/django/middleware/common.py", line 52, in process_request
    if self.should_redirect_with_slash(request):
  File "/home/ubuntu/RockJiggu/venv/lib/python3.6/site-packages/django/middleware/common.py", line 70, in should_redirect_with_slash
    not is_valid_path(request.path_info, urlconf) and
  File "/home/ubuntu/RockJiggu/venv/lib/python3.6/site-packages/django/urls/base.py", line 157, in is_valid_path
    resolve(path, urlconf)
  File "/home/ubuntu/RockJiggu/venv/lib/python3.6/site-packages/django/urls/base.py", line 24, in resolve
    return get_resolver(urlconf).resolve(path)
  File "/home/ubuntu/RockJiggu/venv/lib/python3.6/site-packages/django/urls/resolvers.py", line 536, in resolve
    for pattern in self.url_patterns:
  File "/home/ubuntu/RockJiggu/venv/lib/python3.6/site-packages/django/utils/functional.py", line 80, in __get__
    res = instance.__dict__[self.name] = self.func(instance)
  File "/home/ubuntu/RockJiggu/venv/lib/python3.6/site-packages/django/urls/resolvers.py", line 584, in url_patterns
    patterns = getattr(self.urlconf_module, "urlpatterns", self.urlconf_module)
  File "/home/ubuntu/RockJiggu/venv/lib/python3.6/site-packages/django/utils/functional.py", line 80, in __get__
    res = instance.__dict__[self.name] = self.func(instance)
  File "/home/ubuntu/RockJiggu/venv/lib/python3.6/site-packages/django/urls/resolvers.py", line 577, in urlconf_module
    return import_module(self.urlconf_name)
  File "/home/ubuntu/RockJiggu/venv/lib/python3.6/importlib/__init__.py", line 126, in import_module
    return _bootstrap._gcd_import(name[level:], package, level)
  File "<frozen importlib._bootstrap>", line 994, in _gcd_import
  File "<frozen importlib._bootstrap>", line 971, in _find_and_load
  File "<frozen importlib._bootstrap>", line 955, in _find_and_load_unlocked
  File "<frozen importlib._bootstrap>", line 665, in _load_unlocked
  File "<frozen importlib._bootstrap_external>", line 678, in exec_module
  File "<frozen importlib._bootstrap>", line 219, in _call_with_frames_removed
  File "./RockJiggu/urls.py", line 18, in <module>
    from chatbot import urls as chatbot_url
  File "./chatbot/urls.py", line 2, in <module>
    from . import views
  File "./chatbot/views.py", line 19
    returns self_introduce()
                         ^
SyntaxError: invalid syntax
[pid: 19556|app: 0|req: 10/10] 120.204.202.112 () {34 vars in 477 bytes} [Wed Oct 23 14:05:41 2019] GET /public/index.php => generated 125184 bytes in 57 msecs (HTTP/1.1 500) 1 headers in 63 bytes (1 switches on core 0)
Internal Server Error: /TP/html/public/index.php
Traceback (most recent call last):
  File "/home/ubuntu/RockJiggu/venv/lib/python3.6/site-packages/django/core/handlers/exception.py", line 34, in inner
    response = get_response(request)
  File "/home/ubuntu/RockJiggu/venv/lib/python3.6/site-packages/django/utils/deprecation.py", line 93, in __call__
    response = self.process_request(request)
  File "/home/ubuntu/RockJiggu/venv/lib/python3.6/site-packages/django/middleware/common.py", line 52, in process_request
    if self.should_redirect_with_slash(request):
  File "/home/ubuntu/RockJiggu/venv/lib/python3.6/site-packages/django/middleware/common.py", line 70, in should_redirect_with_slash
    not is_valid_path(request.path_info, urlconf) and
  File "/home/ubuntu/RockJiggu/venv/lib/python3.6/site-packages/django/urls/base.py", line 157, in is_valid_path
    resolve(path, urlconf)
  File "/home/ubuntu/RockJiggu/venv/lib/python3.6/site-packages/django/urls/base.py", line 24, in resolve
    return get_resolver(urlconf).resolve(path)
  File "/home/ubuntu/RockJiggu/venv/lib/python3.6/site-packages/django/urls/resolvers.py", line 536, in resolve
    for pattern in self.url_patterns:
  File "/home/ubuntu/RockJiggu/venv/lib/python3.6/site-packages/django/utils/functional.py", line 80, in __get__
    res = instance.__dict__[self.name] = self.func(instance)
  File "/home/ubuntu/RockJiggu/venv/lib/python3.6/site-packages/django/urls/resolvers.py", line 584, in url_patterns
    patterns = getattr(self.urlconf_module, "urlpatterns", self.urlconf_module)
  File "/home/ubuntu/RockJiggu/venv/lib/python3.6/site-packages/django/utils/functional.py", line 80, in __get__
    res = instance.__dict__[self.name] = self.func(instance)
  File "/home/ubuntu/RockJiggu/venv/lib/python3.6/site-packages/django/urls/resolvers.py", line 577, in urlconf_module
    return import_module(self.urlconf_name)
  File "/home/ubuntu/RockJiggu/venv/lib/python3.6/importlib/__init__.py", line 126, in import_module
    return _bootstrap._gcd_import(name[level:], package, level)
  File "<frozen importlib._bootstrap>", line 994, in _gcd_import
  File "<frozen importlib._bootstrap>", line 971, in _find_and_load
  File "<frozen importlib._bootstrap>", line 955, in _find_and_load_unlocked
  File "<frozen importlib._bootstrap>", line 665, in _load_unlocked
  File "<frozen importlib._bootstrap_external>", line 678, in exec_module
  File "<frozen importlib._bootstrap>", line 219, in _call_with_frames_removed
  File "./RockJiggu/urls.py", line 18, in <module>
    from chatbot import urls as chatbot_url
  File "./chatbot/urls.py", line 2, in <module>
    from . import views
  File "./chatbot/views.py", line 19
    returns self_introduce()
                         ^
SyntaxError: invalid syntax
[pid: 19556|app: 0|req: 11/11] 120.204.202.112 () {34 vars in 493 bytes} [Wed Oct 23 14:05:41 2019] GET /TP/html/public/index.php => generated 125320 bytes in 55 msecs (HTTP/1.1 500) 1 headers in 63 bytes (1 switches on core 0)
Internal Server Error: /elrekt.php
Traceback (most recent call last):
  File "/home/ubuntu/RockJiggu/venv/lib/python3.6/site-packages/django/core/handlers/exception.py", line 34, in inner
    response = get_response(request)
  File "/home/ubuntu/RockJiggu/venv/lib/python3.6/site-packages/django/utils/deprecation.py", line 93, in __call__
    response = self.process_request(request)
  File "/home/ubuntu/RockJiggu/venv/lib/python3.6/site-packages/django/middleware/common.py", line 52, in process_request
    if self.should_redirect_with_slash(request):
  File "/home/ubuntu/RockJiggu/venv/lib/python3.6/site-packages/django/middleware/common.py", line 70, in should_redirect_with_slash
    not is_valid_path(request.path_info, urlconf) and
  File "/home/ubuntu/RockJiggu/venv/lib/python3.6/site-packages/django/urls/base.py", line 157, in is_valid_path
    resolve(path, urlconf)
  File "/home/ubuntu/RockJiggu/venv/lib/python3.6/site-packages/django/urls/base.py", line 24, in resolve
    return get_resolver(urlconf).resolve(path)
  File "/home/ubuntu/RockJiggu/venv/lib/python3.6/site-packages/django/urls/resolvers.py", line 536, in resolve
    for pattern in self.url_patterns:
  File "/home/ubuntu/RockJiggu/venv/lib/python3.6/site-packages/django/utils/functional.py", line 80, in __get__
    res = instance.__dict__[self.name] = self.func(instance)
  File "/home/ubuntu/RockJiggu/venv/lib/python3.6/site-packages/django/urls/resolvers.py", line 584, in url_patterns
    patterns = getattr(self.urlconf_module, "urlpatterns", self.urlconf_module)
  File "/home/ubuntu/RockJiggu/venv/lib/python3.6/site-packages/django/utils/functional.py", line 80, in __get__
    res = instance.__dict__[self.name] = self.func(instance)
  File "/home/ubuntu/RockJiggu/venv/lib/python3.6/site-packages/django/urls/resolvers.py", line 577, in urlconf_module
    return import_module(self.urlconf_name)
  File "/home/ubuntu/RockJiggu/venv/lib/python3.6/importlib/__init__.py", line 126, in import_module
    return _bootstrap._gcd_import(name[level:], package, level)
  File "<frozen importlib._bootstrap>", line 994, in _gcd_import
  File "<frozen importlib._bootstrap>", line 971, in _find_and_load
  File "<frozen importlib._bootstrap>", line 955, in _find_and_load_unlocked
  File "<frozen importlib._bootstrap>", line 665, in _load_unlocked
  File "<frozen importlib._bootstrap_external>", line 678, in exec_module
  File "<frozen importlib._bootstrap>", line 219, in _call_with_frames_removed
  File "./RockJiggu/urls.py", line 18, in <module>
    from chatbot import urls as chatbot_url
  File "./chatbot/urls.py", line 2, in <module>
    from . import views
  File "./chatbot/views.py", line 19
    returns self_introduce()
                         ^
SyntaxError: invalid syntax
[pid: 19556|app: 0|req: 12/12] 120.204.202.112 () {34 vars in 465 bytes} [Wed Oct 23 14:05:42 2019] GET /elrekt.php => generated 125082 bytes in 53 msecs (HTTP/1.1 500) 1 headers in 63 bytes (1 switches on core 0)
Internal Server Error: /index.php
Traceback (most recent call last):
  File "/home/ubuntu/RockJiggu/venv/lib/python3.6/site-packages/django/core/handlers/exception.py", line 34, in inner
    response = get_response(request)
  File "/home/ubuntu/RockJiggu/venv/lib/python3.6/site-packages/django/utils/deprecation.py", line 93, in __call__
    response = self.process_request(request)
  File "/home/ubuntu/RockJiggu/venv/lib/python3.6/site-packages/django/middleware/common.py", line 52, in process_request
    if self.should_redirect_with_slash(request):
  File "/home/ubuntu/RockJiggu/venv/lib/python3.6/site-packages/django/middleware/common.py", line 70, in should_redirect_with_slash
    not is_valid_path(request.path_info, urlconf) and
  File "/home/ubuntu/RockJiggu/venv/lib/python3.6/site-packages/django/urls/base.py", line 157, in is_valid_path
    resolve(path, urlconf)
  File "/home/ubuntu/RockJiggu/venv/lib/python3.6/site-packages/django/urls/base.py", line 24, in resolve
    return get_resolver(urlconf).resolve(path)
  File "/home/ubuntu/RockJiggu/venv/lib/python3.6/site-packages/django/urls/resolvers.py", line 536, in resolve
    for pattern in self.url_patterns:
  File "/home/ubuntu/RockJiggu/venv/lib/python3.6/site-packages/django/utils/functional.py", line 80, in __get__
    res = instance.__dict__[self.name] = self.func(instance)
  File "/home/ubuntu/RockJiggu/venv/lib/python3.6/site-packages/django/urls/resolvers.py", line 584, in url_patterns
    patterns = getattr(self.urlconf_module, "urlpatterns", self.urlconf_module)
  File "/home/ubuntu/RockJiggu/venv/lib/python3.6/site-packages/django/utils/functional.py", line 80, in __get__
    res = instance.__dict__[self.name] = self.func(instance)
  File "/home/ubuntu/RockJiggu/venv/lib/python3.6/site-packages/django/urls/resolvers.py", line 577, in urlconf_module
    return import_module(self.urlconf_name)
  File "/home/ubuntu/RockJiggu/venv/lib/python3.6/importlib/__init__.py", line 126, in import_module
    return _bootstrap._gcd_import(name[level:], package, level)
  File "<frozen importlib._bootstrap>", line 994, in _gcd_import
  File "<frozen importlib._bootstrap>", line 971, in _find_and_load
  File "<frozen importlib._bootstrap>", line 955, in _find_and_load_unlocked
  File "<frozen importlib._bootstrap>", line 665, in _load_unlocked
  File "<frozen importlib._bootstrap_external>", line 678, in exec_module
  File "<frozen importlib._bootstrap>", line 219, in _call_with_frames_removed
  File "./RockJiggu/urls.py", line 18, in <module>
    from chatbot import urls as chatbot_url
  File "./chatbot/urls.py", line 2, in <module>
    from . import views
  File "./chatbot/views.py", line 19
    returns self_introduce()
                         ^
SyntaxError: invalid syntax
[pid: 19556|app: 0|req: 13/13] 120.204.202.112 () {34 vars in 463 bytes} [Wed Oct 23 14:05:42 2019] GET /index.php => generated 125065 bytes in 52 msecs (HTTP/1.1 500) 1 headers in 63 bytes (1 switches on core 0)
Internal Server Error: /
Traceback (most recent call last):
  File "/home/ubuntu/RockJiggu/venv/lib/python3.6/site-packages/django/core/handlers/exception.py", line 34, in inner
    response = get_response(request)
  File "/home/ubuntu/RockJiggu/venv/lib/python3.6/site-packages/django/core/handlers/base.py", line 100, in _get_response
    resolver_match = resolver.resolve(request.path_info)
  File "/home/ubuntu/RockJiggu/venv/lib/python3.6/site-packages/django/urls/resolvers.py", line 536, in resolve
    for pattern in self.url_patterns:
  File "/home/ubuntu/RockJiggu/venv/lib/python3.6/site-packages/django/utils/functional.py", line 80, in __get__
    res = instance.__dict__[self.name] = self.func(instance)
  File "/home/ubuntu/RockJiggu/venv/lib/python3.6/site-packages/django/urls/resolvers.py", line 584, in url_patterns
    patterns = getattr(self.urlconf_module, "urlpatterns", self.urlconf_module)
  File "/home/ubuntu/RockJiggu/venv/lib/python3.6/site-packages/django/utils/functional.py", line 80, in __get__
    res = instance.__dict__[self.name] = self.func(instance)
  File "/home/ubuntu/RockJiggu/venv/lib/python3.6/site-packages/django/urls/resolvers.py", line 577, in urlconf_module
    return import_module(self.urlconf_name)
  File "/home/ubuntu/RockJiggu/venv/lib/python3.6/importlib/__init__.py", line 126, in import_module
    return _bootstrap._gcd_import(name[level:], package, level)
  File "<frozen importlib._bootstrap>", line 994, in _gcd_import
  File "<frozen importlib._bootstrap>", line 971, in _find_and_load
  File "<frozen importlib._bootstrap>", line 955, in _find_and_load_unlocked
  File "<frozen importlib._bootstrap>", line 665, in _load_unlocked
  File "<frozen importlib._bootstrap_external>", line 678, in exec_module
  File "<frozen importlib._bootstrap>", line 219, in _call_with_frames_removed
  File "./RockJiggu/urls.py", line 18, in <module>
    from chatbot import urls as chatbot_url
  File "./chatbot/urls.py", line 2, in <module>
    from . import views
  File "./chatbot/views.py", line 19
    returns self_introduce()
                         ^
SyntaxError: invalid syntax
[pid: 19556|app: 0|req: 14/14] 120.204.202.112 () {34 vars in 448 bytes} [Wed Oct 23 14:05:43 2019] GET / => generated 109295 bytes in 53 msecs (HTTP/1.1 500) 4 headers in 130 bytes (1 switches on core 0)
Internal Server Error: /
Traceback (most recent call last):
  File "/home/ubuntu/RockJiggu/venv/lib/python3.6/site-packages/django/core/handlers/exception.py", line 34, in inner
    response = get_response(request)
  File "/home/ubuntu/RockJiggu/venv/lib/python3.6/site-packages/django/core/handlers/base.py", line 100, in _get_response
    resolver_match = resolver.resolve(request.path_info)
  File "/home/ubuntu/RockJiggu/venv/lib/python3.6/site-packages/django/urls/resolvers.py", line 536, in resolve
    for pattern in self.url_patterns:
  File "/home/ubuntu/RockJiggu/venv/lib/python3.6/site-packages/django/utils/functional.py", line 80, in __get__
    res = instance.__dict__[self.name] = self.func(instance)
  File "/home/ubuntu/RockJiggu/venv/lib/python3.6/site-packages/django/urls/resolvers.py", line 584, in url_patterns
    patterns = getattr(self.urlconf_module, "urlpatterns", self.urlconf_module)
  File "/home/ubuntu/RockJiggu/venv/lib/python3.6/site-packages/django/utils/functional.py", line 80, in __get__
    res = instance.__dict__[self.name] = self.func(instance)
  File "/home/ubuntu/RockJiggu/venv/lib/python3.6/site-packages/django/urls/resolvers.py", line 577, in urlconf_module
    return import_module(self.urlconf_name)
  File "/home/ubuntu/RockJiggu/venv/lib/python3.6/importlib/__init__.py", line 126, in import_module
    return _bootstrap._gcd_import(name[level:], package, level)
  File "<frozen importlib._bootstrap>", line 994, in _gcd_import
  File "<frozen importlib._bootstrap>", line 971, in _find_and_load
  File "<frozen importlib._bootstrap>", line 955, in _find_and_load_unlocked
  File "<frozen importlib._bootstrap>", line 665, in _load_unlocked
  File "<frozen importlib._bootstrap_external>", line 678, in exec_module
  File "<frozen importlib._bootstrap>", line 219, in _call_with_frames_removed
  File "./RockJiggu/urls.py", line 18, in <module>
    from chatbot import urls as chatbot_url
  File "./chatbot/urls.py", line 2, in <module>
    from . import views
  File "./chatbot/views.py", line 19
    returns self_introduce()
                         ^
SyntaxError: invalid syntax
[pid: 19556|app: 0|req: 15/15] 208.38.245.163 () {32 vars in 446 bytes} [Wed Oct 23 15:49:30 2019] GET / => generated 109189 bytes in 53 msecs (HTTP/1.1 500) 4 headers in 130 bytes (2 switches on core 0)
Internal Server Error: /TP/public/index.php
Traceback (most recent call last):
  File "/home/ubuntu/RockJiggu/venv/lib/python3.6/site-packages/django/core/handlers/exception.py", line 34, in inner
    response = get_response(request)
  File "/home/ubuntu/RockJiggu/venv/lib/python3.6/site-packages/django/utils/deprecation.py", line 93, in __call__
    response = self.process_request(request)
  File "/home/ubuntu/RockJiggu/venv/lib/python3.6/site-packages/django/middleware/common.py", line 52, in process_request
    if self.should_redirect_with_slash(request):
  File "/home/ubuntu/RockJiggu/venv/lib/python3.6/site-packages/django/middleware/common.py", line 70, in should_redirect_with_slash
    not is_valid_path(request.path_info, urlconf) and
  File "/home/ubuntu/RockJiggu/venv/lib/python3.6/site-packages/django/urls/base.py", line 157, in is_valid_path
    resolve(path, urlconf)
  File "/home/ubuntu/RockJiggu/venv/lib/python3.6/site-packages/django/urls/base.py", line 24, in resolve
    return get_resolver(urlconf).resolve(path)
  File "/home/ubuntu/RockJiggu/venv/lib/python3.6/site-packages/django/urls/resolvers.py", line 536, in resolve
    for pattern in self.url_patterns:
  File "/home/ubuntu/RockJiggu/venv/lib/python3.6/site-packages/django/utils/functional.py", line 80, in __get__
    res = instance.__dict__[self.name] = self.func(instance)
  File "/home/ubuntu/RockJiggu/venv/lib/python3.6/site-packages/django/urls/resolvers.py", line 584, in url_patterns
    patterns = getattr(self.urlconf_module, "urlpatterns", self.urlconf_module)
  File "/home/ubuntu/RockJiggu/venv/lib/python3.6/site-packages/django/utils/functional.py", line 80, in __get__
    res = instance.__dict__[self.name] = self.func(instance)
  File "/home/ubuntu/RockJiggu/venv/lib/python3.6/site-packages/django/urls/resolvers.py", line 577, in urlconf_module
    return import_module(self.urlconf_name)
  File "/home/ubuntu/RockJiggu/venv/lib/python3.6/importlib/__init__.py", line 126, in import_module
    return _bootstrap._gcd_import(name[level:], package, level)
  File "<frozen importlib._bootstrap>", line 994, in _gcd_import
  File "<frozen importlib._bootstrap>", line 971, in _find_and_load
  File "<frozen importlib._bootstrap>", line 955, in _find_and_load_unlocked
  File "<frozen importlib._bootstrap>", line 665, in _load_unlocked
  File "<frozen importlib._bootstrap_external>", line 678, in exec_module
  File "<frozen importlib._bootstrap>", line 219, in _call_with_frames_removed
  File "./RockJiggu/urls.py", line 18, in <module>
    from chatbot import urls as chatbot_url
  File "./chatbot/urls.py", line 2, in <module>
    from . import views
  File "./chatbot/views.py", line 19
    returns self_introduce()
                         ^
SyntaxError: invalid syntax
[pid: 19556|app: 0|req: 16/16] 222.171.81.7 () {34 vars in 480 bytes} [Wed Oct 23 17:56:48 2019] GET /TP/public/index.php => generated 125232 bytes in 55 msecs (HTTP/1.1 500) 1 headers in 63 bytes (2 switches on core 0)
Internal Server Error: /TP/index.php
Traceback (most recent call last):
  File "/home/ubuntu/RockJiggu/venv/lib/python3.6/site-packages/django/core/handlers/exception.py", line 34, in inner
    response = get_response(request)
  File "/home/ubuntu/RockJiggu/venv/lib/python3.6/site-packages/django/utils/deprecation.py", line 93, in __call__
    response = self.process_request(request)
  File "/home/ubuntu/RockJiggu/venv/lib/python3.6/site-packages/django/middleware/common.py", line 52, in process_request
    if self.should_redirect_with_slash(request):
  File "/home/ubuntu/RockJiggu/venv/lib/python3.6/site-packages/django/middleware/common.py", line 70, in should_redirect_with_slash
    not is_valid_path(request.path_info, urlconf) and
  File "/home/ubuntu/RockJiggu/venv/lib/python3.6/site-packages/django/urls/base.py", line 157, in is_valid_path
    resolve(path, urlconf)
  File "/home/ubuntu/RockJiggu/venv/lib/python3.6/site-packages/django/urls/base.py", line 24, in resolve
    return get_resolver(urlconf).resolve(path)
  File "/home/ubuntu/RockJiggu/venv/lib/python3.6/site-packages/django/urls/resolvers.py", line 536, in resolve
    for pattern in self.url_patterns:
  File "/home/ubuntu/RockJiggu/venv/lib/python3.6/site-packages/django/utils/functional.py", line 80, in __get__
    res = instance.__dict__[self.name] = self.func(instance)
  File "/home/ubuntu/RockJiggu/venv/lib/python3.6/site-packages/django/urls/resolvers.py", line 584, in url_patterns
    patterns = getattr(self.urlconf_module, "urlpatterns", self.urlconf_module)
  File "/home/ubuntu/RockJiggu/venv/lib/python3.6/site-packages/django/utils/functional.py", line 80, in __get__
    res = instance.__dict__[self.name] = self.func(instance)
  File "/home/ubuntu/RockJiggu/venv/lib/python3.6/site-packages/django/urls/resolvers.py", line 577, in urlconf_module
    return import_module(self.urlconf_name)
  File "/home/ubuntu/RockJiggu/venv/lib/python3.6/importlib/__init__.py", line 126, in import_module
    return _bootstrap._gcd_import(name[level:], package, level)
  File "<frozen importlib._bootstrap>", line 994, in _gcd_import
  File "<frozen importlib._bootstrap>", line 971, in _find_and_load
  File "<frozen importlib._bootstrap>", line 955, in _find_and_load_unlocked
  File "<frozen importlib._bootstrap>", line 665, in _load_unlocked
  File "<frozen importlib._bootstrap_external>", line 678, in exec_module
  File "<frozen importlib._bootstrap>", line 219, in _call_with_frames_removed
  File "./RockJiggu/urls.py", line 18, in <module>
    from chatbot import urls as chatbot_url
  File "./chatbot/urls.py", line 2, in <module>
    from . import views
  File "./chatbot/views.py", line 19
    returns self_introduce()
                         ^
SyntaxError: invalid syntax
[pid: 19556|app: 0|req: 17/17] 222.171.81.7 () {34 vars in 466 bytes} [Wed Oct 23 17:56:48 2019] GET /TP/index.php => generated 125113 bytes in 56 msecs (HTTP/1.1 500) 1 headers in 63 bytes (1 switches on core 0)
Internal Server Error: /thinkphp/html/public/index.php
Traceback (most recent call last):
  File "/home/ubuntu/RockJiggu/venv/lib/python3.6/site-packages/django/core/handlers/exception.py", line 34, in inner
    response = get_response(request)
  File "/home/ubuntu/RockJiggu/venv/lib/python3.6/site-packages/django/utils/deprecation.py", line 93, in __call__
    response = self.process_request(request)
  File "/home/ubuntu/RockJiggu/venv/lib/python3.6/site-packages/django/middleware/common.py", line 52, in process_request
    if self.should_redirect_with_slash(request):
  File "/home/ubuntu/RockJiggu/venv/lib/python3.6/site-packages/django/middleware/common.py", line 70, in should_redirect_with_slash
    not is_valid_path(request.path_info, urlconf) and
  File "/home/ubuntu/RockJiggu/venv/lib/python3.6/site-packages/django/urls/base.py", line 157, in is_valid_path
    resolve(path, urlconf)
  File "/home/ubuntu/RockJiggu/venv/lib/python3.6/site-packages/django/urls/base.py", line 24, in resolve
    return get_resolver(urlconf).resolve(path)
  File "/home/ubuntu/RockJiggu/venv/lib/python3.6/site-packages/django/urls/resolvers.py", line 536, in resolve
    for pattern in self.url_patterns:
  File "/home/ubuntu/RockJiggu/venv/lib/python3.6/site-packages/django/utils/functional.py", line 80, in __get__
    res = instance.__dict__[self.name] = self.func(instance)
  File "/home/ubuntu/RockJiggu/venv/lib/python3.6/site-packages/django/urls/resolvers.py", line 584, in url_patterns
    patterns = getattr(self.urlconf_module, "urlpatterns", self.urlconf_module)
  File "/home/ubuntu/RockJiggu/venv/lib/python3.6/site-packages/django/utils/functional.py", line 80, in __get__
    res = instance.__dict__[self.name] = self.func(instance)
  File "/home/ubuntu/RockJiggu/venv/lib/python3.6/site-packages/django/urls/resolvers.py", line 577, in urlconf_module
    return import_module(self.urlconf_name)
  File "/home/ubuntu/RockJiggu/venv/lib/python3.6/importlib/__init__.py", line 126, in import_module
    return _bootstrap._gcd_import(name[level:], package, level)
  File "<frozen importlib._bootstrap>", line 994, in _gcd_import
  File "<frozen importlib._bootstrap>", line 971, in _find_and_load
  File "<frozen importlib._bootstrap>", line 955, in _find_and_load_unlocked
  File "<frozen importlib._bootstrap>", line 665, in _load_unlocked
  File "<frozen importlib._bootstrap_external>", line 678, in exec_module
  File "<frozen importlib._bootstrap>", line 219, in _call_with_frames_removed
  File "./RockJiggu/urls.py", line 18, in <module>
    from chatbot import urls as chatbot_url
  File "./chatbot/urls.py", line 2, in <module>
    from . import views
  File "./chatbot/views.py", line 19
    returns self_introduce()
                         ^
SyntaxError: invalid syntax
[pid: 19556|app: 0|req: 18/18] 222.171.81.7 () {34 vars in 502 bytes} [Wed Oct 23 17:56:49 2019] GET /thinkphp/html/public/index.php => generated 125419 bytes in 53 msecs (HTTP/1.1 500) 1 headers in 63 bytes (1 switches on core 0)
Internal Server Error: /html/public/index.php
Traceback (most recent call last):
  File "/home/ubuntu/RockJiggu/venv/lib/python3.6/site-packages/django/core/handlers/exception.py", line 34, in inner
    response = get_response(request)
  File "/home/ubuntu/RockJiggu/venv/lib/python3.6/site-packages/django/utils/deprecation.py", line 93, in __call__
    response = self.process_request(request)
  File "/home/ubuntu/RockJiggu/venv/lib/python3.6/site-packages/django/middleware/common.py", line 52, in process_request
    if self.should_redirect_with_slash(request):
  File "/home/ubuntu/RockJiggu/venv/lib/python3.6/site-packages/django/middleware/common.py", line 70, in should_redirect_with_slash
    not is_valid_path(request.path_info, urlconf) and
  File "/home/ubuntu/RockJiggu/venv/lib/python3.6/site-packages/django/urls/base.py", line 157, in is_valid_path
    resolve(path, urlconf)
  File "/home/ubuntu/RockJiggu/venv/lib/python3.6/site-packages/django/urls/base.py", line 24, in resolve
    return get_resolver(urlconf).resolve(path)
  File "/home/ubuntu/RockJiggu/venv/lib/python3.6/site-packages/django/urls/resolvers.py", line 536, in resolve
    for pattern in self.url_patterns:
  File "/home/ubuntu/RockJiggu/venv/lib/python3.6/site-packages/django/utils/functional.py", line 80, in __get__
    res = instance.__dict__[self.name] = self.func(instance)
  File "/home/ubuntu/RockJiggu/venv/lib/python3.6/site-packages/django/urls/resolvers.py", line 584, in url_patterns
    patterns = getattr(self.urlconf_module, "urlpatterns", self.urlconf_module)
  File "/home/ubuntu/RockJiggu/venv/lib/python3.6/site-packages/django/utils/functional.py", line 80, in __get__
    res = instance.__dict__[self.name] = self.func(instance)
  File "/home/ubuntu/RockJiggu/venv/lib/python3.6/site-packages/django/urls/resolvers.py", line 577, in urlconf_module
    return import_module(self.urlconf_name)
  File "/home/ubuntu/RockJiggu/venv/lib/python3.6/importlib/__init__.py", line 126, in import_module
    return _bootstrap._gcd_import(name[level:], package, level)
  File "<frozen importlib._bootstrap>", line 994, in _gcd_import
  File "<frozen importlib._bootstrap>", line 971, in _find_and_load
  File "<frozen importlib._bootstrap>", line 955, in _find_and_load_unlocked
  File "<frozen importlib._bootstrap>", line 665, in _load_unlocked
  File "<frozen importlib._bootstrap_external>", line 678, in exec_module
  File "<frozen importlib._bootstrap>", line 219, in _call_with_frames_removed
  File "./RockJiggu/urls.py", line 18, in <module>
    from chatbot import urls as chatbot_url
  File "./chatbot/urls.py", line 2, in <module>
    from . import views
  File "./chatbot/views.py", line 19
    returns self_introduce()
                         ^
SyntaxError: invalid syntax
[pid: 19556|app: 0|req: 19/19] 222.171.81.7 () {34 vars in 484 bytes} [Wed Oct 23 17:56:49 2019] GET /html/public/index.php => generated 125266 bytes in 53 msecs (HTTP/1.1 500) 1 headers in 63 bytes (1 switches on core 0)
Internal Server Error: /public/index.php
Traceback (most recent call last):
  File "/home/ubuntu/RockJiggu/venv/lib/python3.6/site-packages/django/core/handlers/exception.py", line 34, in inner
    response = get_response(request)
  File "/home/ubuntu/RockJiggu/venv/lib/python3.6/site-packages/django/utils/deprecation.py", line 93, in __call__
    response = self.process_request(request)
  File "/home/ubuntu/RockJiggu/venv/lib/python3.6/site-packages/django/middleware/common.py", line 52, in process_request
    if self.should_redirect_with_slash(request):
  File "/home/ubuntu/RockJiggu/venv/lib/python3.6/site-packages/django/middleware/common.py", line 70, in should_redirect_with_slash
    not is_valid_path(request.path_info, urlconf) and
  File "/home/ubuntu/RockJiggu/venv/lib/python3.6/site-packages/django/urls/base.py", line 157, in is_valid_path
    resolve(path, urlconf)
  File "/home/ubuntu/RockJiggu/venv/lib/python3.6/site-packages/django/urls/base.py", line 24, in resolve
    return get_resolver(urlconf).resolve(path)
  File "/home/ubuntu/RockJiggu/venv/lib/python3.6/site-packages/django/urls/resolvers.py", line 536, in resolve
    for pattern in self.url_patterns:
  File "/home/ubuntu/RockJiggu/venv/lib/python3.6/site-packages/django/utils/functional.py", line 80, in __get__
    res = instance.__dict__[self.name] = self.func(instance)
  File "/home/ubuntu/RockJiggu/venv/lib/python3.6/site-packages/django/urls/resolvers.py", line 584, in url_patterns
    patterns = getattr(self.urlconf_module, "urlpatterns", self.urlconf_module)
  File "/home/ubuntu/RockJiggu/venv/lib/python3.6/site-packages/django/utils/functional.py", line 80, in __get__
    res = instance.__dict__[self.name] = self.func(instance)
  File "/home/ubuntu/RockJiggu/venv/lib/python3.6/site-packages/django/urls/resolvers.py", line 577, in urlconf_module
    return import_module(self.urlconf_name)
  File "/home/ubuntu/RockJiggu/venv/lib/python3.6/importlib/__init__.py", line 126, in import_module
    return _bootstrap._gcd_import(name[level:], package, level)
  File "<frozen importlib._bootstrap>", line 994, in _gcd_import
  File "<frozen importlib._bootstrap>", line 971, in _find_and_load
  File "<frozen importlib._bootstrap>", line 955, in _find_and_load_unlocked
  File "<frozen importlib._bootstrap>", line 665, in _load_unlocked
  File "<frozen importlib._bootstrap_external>", line 678, in exec_module
  File "<frozen importlib._bootstrap>", line 219, in _call_with_frames_removed
  File "./RockJiggu/urls.py", line 18, in <module>
    from chatbot import urls as chatbot_url
  File "./chatbot/urls.py", line 2, in <module>
    from . import views
  File "./chatbot/views.py", line 19
    returns self_introduce()
                         ^
SyntaxError: invalid syntax
[pid: 19556|app: 0|req: 20/20] 222.171.81.7 () {34 vars in 474 bytes} [Wed Oct 23 17:56:49 2019] GET /public/index.php => generated 125181 bytes in 53 msecs (HTTP/1.1 500) 1 headers in 63 bytes (1 switches on core 0)
Internal Server Error: /TP/html/public/index.php
Traceback (most recent call last):
  File "/home/ubuntu/RockJiggu/venv/lib/python3.6/site-packages/django/core/handlers/exception.py", line 34, in inner
    response = get_response(request)
  File "/home/ubuntu/RockJiggu/venv/lib/python3.6/site-packages/django/utils/deprecation.py", line 93, in __call__
    response = self.process_request(request)
  File "/home/ubuntu/RockJiggu/venv/lib/python3.6/site-packages/django/middleware/common.py", line 52, in process_request
    if self.should_redirect_with_slash(request):
  File "/home/ubuntu/RockJiggu/venv/lib/python3.6/site-packages/django/middleware/common.py", line 70, in should_redirect_with_slash
    not is_valid_path(request.path_info, urlconf) and
  File "/home/ubuntu/RockJiggu/venv/lib/python3.6/site-packages/django/urls/base.py", line 157, in is_valid_path
    resolve(path, urlconf)
  File "/home/ubuntu/RockJiggu/venv/lib/python3.6/site-packages/django/urls/base.py", line 24, in resolve
    return get_resolver(urlconf).resolve(path)
  File "/home/ubuntu/RockJiggu/venv/lib/python3.6/site-packages/django/urls/resolvers.py", line 536, in resolve
    for pattern in self.url_patterns:
  File "/home/ubuntu/RockJiggu/venv/lib/python3.6/site-packages/django/utils/functional.py", line 80, in __get__
    res = instance.__dict__[self.name] = self.func(instance)
  File "/home/ubuntu/RockJiggu/venv/lib/python3.6/site-packages/django/urls/resolvers.py", line 584, in url_patterns
    patterns = getattr(self.urlconf_module, "urlpatterns", self.urlconf_module)
  File "/home/ubuntu/RockJiggu/venv/lib/python3.6/site-packages/django/utils/functional.py", line 80, in __get__
    res = instance.__dict__[self.name] = self.func(instance)
  File "/home/ubuntu/RockJiggu/venv/lib/python3.6/site-packages/django/urls/resolvers.py", line 577, in urlconf_module
    return import_module(self.urlconf_name)
  File "/home/ubuntu/RockJiggu/venv/lib/python3.6/importlib/__init__.py", line 126, in import_module
    return _bootstrap._gcd_import(name[level:], package, level)
  File "<frozen importlib._bootstrap>", line 994, in _gcd_import
  File "<frozen importlib._bootstrap>", line 971, in _find_and_load
  File "<frozen importlib._bootstrap>", line 955, in _find_and_load_unlocked
  File "<frozen importlib._bootstrap>", line 665, in _load_unlocked
  File "<frozen importlib._bootstrap_external>", line 678, in exec_module
  File "<frozen importlib._bootstrap>", line 219, in _call_with_frames_removed
  File "./RockJiggu/urls.py", line 18, in <module>
    from chatbot import urls as chatbot_url
  File "./chatbot/urls.py", line 2, in <module>
    from . import views
  File "./chatbot/views.py", line 19
    returns self_introduce()
                         ^
SyntaxError: invalid syntax
[pid: 19556|app: 0|req: 21/21] 222.171.81.7 () {34 vars in 490 bytes} [Wed Oct 23 17:56:50 2019] GET /TP/html/public/index.php => generated 125317 bytes in 54 msecs (HTTP/1.1 500) 1 headers in 63 bytes (1 switches on core 0)
Internal Server Error: /elrekt.php
Traceback (most recent call last):
  File "/home/ubuntu/RockJiggu/venv/lib/python3.6/site-packages/django/core/handlers/exception.py", line 34, in inner
    response = get_response(request)
  File "/home/ubuntu/RockJiggu/venv/lib/python3.6/site-packages/django/utils/deprecation.py", line 93, in __call__
    response = self.process_request(request)
  File "/home/ubuntu/RockJiggu/venv/lib/python3.6/site-packages/django/middleware/common.py", line 52, in process_request
    if self.should_redirect_with_slash(request):
  File "/home/ubuntu/RockJiggu/venv/lib/python3.6/site-packages/django/middleware/common.py", line 70, in should_redirect_with_slash
    not is_valid_path(request.path_info, urlconf) and
  File "/home/ubuntu/RockJiggu/venv/lib/python3.6/site-packages/django/urls/base.py", line 157, in is_valid_path
    resolve(path, urlconf)
  File "/home/ubuntu/RockJiggu/venv/lib/python3.6/site-packages/django/urls/base.py", line 24, in resolve
    return get_resolver(urlconf).resolve(path)
  File "/home/ubuntu/RockJiggu/venv/lib/python3.6/site-packages/django/urls/resolvers.py", line 536, in resolve
    for pattern in self.url_patterns:
  File "/home/ubuntu/RockJiggu/venv/lib/python3.6/site-packages/django/utils/functional.py", line 80, in __get__
    res = instance.__dict__[self.name] = self.func(instance)
  File "/home/ubuntu/RockJiggu/venv/lib/python3.6/site-packages/django/urls/resolvers.py", line 584, in url_patterns
    patterns = getattr(self.urlconf_module, "urlpatterns", self.urlconf_module)
  File "/home/ubuntu/RockJiggu/venv/lib/python3.6/site-packages/django/utils/functional.py", line 80, in __get__
    res = instance.__dict__[self.name] = self.func(instance)
  File "/home/ubuntu/RockJiggu/venv/lib/python3.6/site-packages/django/urls/resolvers.py", line 577, in urlconf_module
    return import_module(self.urlconf_name)
  File "/home/ubuntu/RockJiggu/venv/lib/python3.6/importlib/__init__.py", line 126, in import_module
    return _bootstrap._gcd_import(name[level:], package, level)
  File "<frozen importlib._bootstrap>", line 994, in _gcd_import
  File "<frozen importlib._bootstrap>", line 971, in _find_and_load
  File "<frozen importlib._bootstrap>", line 955, in _find_and_load_unlocked
  File "<frozen importlib._bootstrap>", line 665, in _load_unlocked
  File "<frozen importlib._bootstrap_external>", line 678, in exec_module
  File "<frozen importlib._bootstrap>", line 219, in _call_with_frames_removed
  File "./RockJiggu/urls.py", line 18, in <module>
    from chatbot import urls as chatbot_url
  File "./chatbot/urls.py", line 2, in <module>
    from . import views
  File "./chatbot/views.py", line 19
    returns self_introduce()
                         ^
SyntaxError: invalid syntax
[pid: 19556|app: 0|req: 22/22] 222.171.81.7 () {34 vars in 462 bytes} [Wed Oct 23 17:56:50 2019] GET /elrekt.php => generated 125079 bytes in 50 msecs (HTTP/1.1 500) 1 headers in 63 bytes (1 switches on core 0)
Internal Server Error: /index.php
Traceback (most recent call last):
  File "/home/ubuntu/RockJiggu/venv/lib/python3.6/site-packages/django/core/handlers/exception.py", line 34, in inner
    response = get_response(request)
  File "/home/ubuntu/RockJiggu/venv/lib/python3.6/site-packages/django/utils/deprecation.py", line 93, in __call__
    response = self.process_request(request)
  File "/home/ubuntu/RockJiggu/venv/lib/python3.6/site-packages/django/middleware/common.py", line 52, in process_request
    if self.should_redirect_with_slash(request):
  File "/home/ubuntu/RockJiggu/venv/lib/python3.6/site-packages/django/middleware/common.py", line 70, in should_redirect_with_slash
    not is_valid_path(request.path_info, urlconf) and
  File "/home/ubuntu/RockJiggu/venv/lib/python3.6/site-packages/django/urls/base.py", line 157, in is_valid_path
    resolve(path, urlconf)
  File "/home/ubuntu/RockJiggu/venv/lib/python3.6/site-packages/django/urls/base.py", line 24, in resolve
    return get_resolver(urlconf).resolve(path)
  File "/home/ubuntu/RockJiggu/venv/lib/python3.6/site-packages/django/urls/resolvers.py", line 536, in resolve
    for pattern in self.url_patterns:
  File "/home/ubuntu/RockJiggu/venv/lib/python3.6/site-packages/django/utils/functional.py", line 80, in __get__
    res = instance.__dict__[self.name] = self.func(instance)
  File "/home/ubuntu/RockJiggu/venv/lib/python3.6/site-packages/django/urls/resolvers.py", line 584, in url_patterns
    patterns = getattr(self.urlconf_module, "urlpatterns", self.urlconf_module)
  File "/home/ubuntu/RockJiggu/venv/lib/python3.6/site-packages/django/utils/functional.py", line 80, in __get__
    res = instance.__dict__[self.name] = self.func(instance)
  File "/home/ubuntu/RockJiggu/venv/lib/python3.6/site-packages/django/urls/resolvers.py", line 577, in urlconf_module
    return import_module(self.urlconf_name)
  File "/home/ubuntu/RockJiggu/venv/lib/python3.6/importlib/__init__.py", line 126, in import_module
    return _bootstrap._gcd_import(name[level:], package, level)
  File "<frozen importlib._bootstrap>", line 994, in _gcd_import
  File "<frozen importlib._bootstrap>", line 971, in _find_and_load
  File "<frozen importlib._bootstrap>", line 955, in _find_and_load_unlocked
  File "<frozen importlib._bootstrap>", line 665, in _load_unlocked
  File "<frozen importlib._bootstrap_external>", line 678, in exec_module
  File "<frozen importlib._bootstrap>", line 219, in _call_with_frames_removed
  File "./RockJiggu/urls.py", line 18, in <module>
    from chatbot import urls as chatbot_url
  File "./chatbot/urls.py", line 2, in <module>
    from . import views
  File "./chatbot/views.py", line 19
    returns self_introduce()
                         ^
SyntaxError: invalid syntax
[pid: 19556|app: 0|req: 23/23] 222.171.81.7 () {34 vars in 460 bytes} [Wed Oct 23 17:56:50 2019] GET /index.php => generated 125062 bytes in 50 msecs (HTTP/1.1 500) 1 headers in 63 bytes (1 switches on core 0)
Internal Server Error: /
Traceback (most recent call last):
  File "/home/ubuntu/RockJiggu/venv/lib/python3.6/site-packages/django/core/handlers/exception.py", line 34, in inner
    response = get_response(request)
  File "/home/ubuntu/RockJiggu/venv/lib/python3.6/site-packages/django/core/handlers/base.py", line 100, in _get_response
    resolver_match = resolver.resolve(request.path_info)
  File "/home/ubuntu/RockJiggu/venv/lib/python3.6/site-packages/django/urls/resolvers.py", line 536, in resolve
    for pattern in self.url_patterns:
  File "/home/ubuntu/RockJiggu/venv/lib/python3.6/site-packages/django/utils/functional.py", line 80, in __get__
    res = instance.__dict__[self.name] = self.func(instance)
  File "/home/ubuntu/RockJiggu/venv/lib/python3.6/site-packages/django/urls/resolvers.py", line 584, in url_patterns
    patterns = getattr(self.urlconf_module, "urlpatterns", self.urlconf_module)
  File "/home/ubuntu/RockJiggu/venv/lib/python3.6/site-packages/django/utils/functional.py", line 80, in __get__
    res = instance.__dict__[self.name] = self.func(instance)
  File "/home/ubuntu/RockJiggu/venv/lib/python3.6/site-packages/django/urls/resolvers.py", line 577, in urlconf_module
    return import_module(self.urlconf_name)
  File "/home/ubuntu/RockJiggu/venv/lib/python3.6/importlib/__init__.py", line 126, in import_module
    return _bootstrap._gcd_import(name[level:], package, level)
  File "<frozen importlib._bootstrap>", line 994, in _gcd_import
  File "<frozen importlib._bootstrap>", line 971, in _find_and_load
  File "<frozen importlib._bootstrap>", line 955, in _find_and_load_unlocked
  File "<frozen importlib._bootstrap>", line 665, in _load_unlocked
  File "<frozen importlib._bootstrap_external>", line 678, in exec_module
  File "<frozen importlib._bootstrap>", line 219, in _call_with_frames_removed
  File "./RockJiggu/urls.py", line 18, in <module>
    from chatbot import urls as chatbot_url
  File "./chatbot/urls.py", line 2, in <module>
    from . import views
  File "./chatbot/views.py", line 19
    returns self_introduce()
                         ^
SyntaxError: invalid syntax
[pid: 19556|app: 0|req: 24/24] 222.171.81.7 () {34 vars in 445 bytes} [Wed Oct 23 17:56:51 2019] GET / => generated 109292 bytes in 49 msecs (HTTP/1.1 500) 4 headers in 130 bytes (1 switches on core 0)
Internal Server Error: /
Traceback (most recent call last):
  File "/home/ubuntu/RockJiggu/venv/lib/python3.6/site-packages/django/core/handlers/exception.py", line 34, in inner
    response = get_response(request)
  File "/home/ubuntu/RockJiggu/venv/lib/python3.6/site-packages/django/core/handlers/base.py", line 100, in _get_response
    resolver_match = resolver.resolve(request.path_info)
  File "/home/ubuntu/RockJiggu/venv/lib/python3.6/site-packages/django/urls/resolvers.py", line 536, in resolve
    for pattern in self.url_patterns:
  File "/home/ubuntu/RockJiggu/venv/lib/python3.6/site-packages/django/utils/functional.py", line 80, in __get__
    res = instance.__dict__[self.name] = self.func(instance)
  File "/home/ubuntu/RockJiggu/venv/lib/python3.6/site-packages/django/urls/resolvers.py", line 584, in url_patterns
    patterns = getattr(self.urlconf_module, "urlpatterns", self.urlconf_module)
  File "/home/ubuntu/RockJiggu/venv/lib/python3.6/site-packages/django/utils/functional.py", line 80, in __get__
    res = instance.__dict__[self.name] = self.func(instance)
  File "/home/ubuntu/RockJiggu/venv/lib/python3.6/site-packages/django/urls/resolvers.py", line 577, in urlconf_module
    return import_module(self.urlconf_name)
  File "/home/ubuntu/RockJiggu/venv/lib/python3.6/importlib/__init__.py", line 126, in import_module
    return _bootstrap._gcd_import(name[level:], package, level)
  File "<frozen importlib._bootstrap>", line 994, in _gcd_import
  File "<frozen importlib._bootstrap>", line 971, in _find_and_load
  File "<frozen importlib._bootstrap>", line 955, in _find_and_load_unlocked
  File "<frozen importlib._bootstrap>", line 665, in _load_unlocked
  File "<frozen importlib._bootstrap_external>", line 678, in exec_module
  File "<frozen importlib._bootstrap>", line 219, in _call_with_frames_removed
  File "./RockJiggu/urls.py", line 18, in <module>
    from chatbot import urls as chatbot_url
  File "./chatbot/urls.py", line 2, in <module>
    from . import views
  File "./chatbot/views.py", line 19
    returns self_introduce()
                         ^
SyntaxError: invalid syntax
[pid: 19556|app: 0|req: 25/25] 88.250.187.213 () {32 vars in 452 bytes} [Wed Oct 23 19:04:13 2019] GET / => generated 109195 bytes in 46 msecs (HTTP/1.1 500) 4 headers in 130 bytes (2 switches on core 0)
Internal Server Error: /
Traceback (most recent call last):
  File "/home/ubuntu/RockJiggu/venv/lib/python3.6/site-packages/django/core/handlers/exception.py", line 34, in inner
    response = get_response(request)
  File "/home/ubuntu/RockJiggu/venv/lib/python3.6/site-packages/django/core/handlers/base.py", line 100, in _get_response
    resolver_match = resolver.resolve(request.path_info)
  File "/home/ubuntu/RockJiggu/venv/lib/python3.6/site-packages/django/urls/resolvers.py", line 536, in resolve
    for pattern in self.url_patterns:
  File "/home/ubuntu/RockJiggu/venv/lib/python3.6/site-packages/django/utils/functional.py", line 80, in __get__
    res = instance.__dict__[self.name] = self.func(instance)
  File "/home/ubuntu/RockJiggu/venv/lib/python3.6/site-packages/django/urls/resolvers.py", line 584, in url_patterns
    patterns = getattr(self.urlconf_module, "urlpatterns", self.urlconf_module)
  File "/home/ubuntu/RockJiggu/venv/lib/python3.6/site-packages/django/utils/functional.py", line 80, in __get__
    res = instance.__dict__[self.name] = self.func(instance)
  File "/home/ubuntu/RockJiggu/venv/lib/python3.6/site-packages/django/urls/resolvers.py", line 577, in urlconf_module
    return import_module(self.urlconf_name)
  File "/home/ubuntu/RockJiggu/venv/lib/python3.6/importlib/__init__.py", line 126, in import_module
    return _bootstrap._gcd_import(name[level:], package, level)
  File "<frozen importlib._bootstrap>", line 994, in _gcd_import
  File "<frozen importlib._bootstrap>", line 971, in _find_and_load
  File "<frozen importlib._bootstrap>", line 955, in _find_and_load_unlocked
  File "<frozen importlib._bootstrap>", line 665, in _load_unlocked
  File "<frozen importlib._bootstrap_external>", line 678, in exec_module
  File "<frozen importlib._bootstrap>", line 219, in _call_with_frames_removed
  File "./RockJiggu/urls.py", line 18, in <module>
    from chatbot import urls as chatbot_url
  File "./chatbot/urls.py", line 2, in <module>
    from . import views
  File "./chatbot/views.py", line 19
    returns self_introduce()
                         ^
SyntaxError: invalid syntax
[pid: 19556|app: 0|req: 26/26] 36.84.103.23 () {32 vars in 443 bytes} [Wed Oct 23 19:46:11 2019] GET / => generated 109186 bytes in 51 msecs (HTTP/1.1 500) 4 headers in 130 bytes (2 switches on core 0)
Internal Server Error: /
Traceback (most recent call last):
  File "/home/ubuntu/RockJiggu/venv/lib/python3.6/site-packages/django/core/handlers/exception.py", line 34, in inner
    response = get_response(request)
  File "/home/ubuntu/RockJiggu/venv/lib/python3.6/site-packages/django/core/handlers/base.py", line 100, in _get_response
    resolver_match = resolver.resolve(request.path_info)
  File "/home/ubuntu/RockJiggu/venv/lib/python3.6/site-packages/django/urls/resolvers.py", line 536, in resolve
    for pattern in self.url_patterns:
  File "/home/ubuntu/RockJiggu/venv/lib/python3.6/site-packages/django/utils/functional.py", line 80, in __get__
    res = instance.__dict__[self.name] = self.func(instance)
  File "/home/ubuntu/RockJiggu/venv/lib/python3.6/site-packages/django/urls/resolvers.py", line 584, in url_patterns
    patterns = getattr(self.urlconf_module, "urlpatterns", self.urlconf_module)
  File "/home/ubuntu/RockJiggu/venv/lib/python3.6/site-packages/django/utils/functional.py", line 80, in __get__
    res = instance.__dict__[self.name] = self.func(instance)
  File "/home/ubuntu/RockJiggu/venv/lib/python3.6/site-packages/django/urls/resolvers.py", line 577, in urlconf_module
    return import_module(self.urlconf_name)
  File "/home/ubuntu/RockJiggu/venv/lib/python3.6/importlib/__init__.py", line 126, in import_module
    return _bootstrap._gcd_import(name[level:], package, level)
  File "<frozen importlib._bootstrap>", line 994, in _gcd_import
  File "<frozen importlib._bootstrap>", line 971, in _find_and_load
  File "<frozen importlib._bootstrap>", line 955, in _find_and_load_unlocked
  File "<frozen importlib._bootstrap>", line 665, in _load_unlocked
  File "<frozen importlib._bootstrap_external>", line 678, in exec_module
  File "<frozen importlib._bootstrap>", line 219, in _call_with_frames_removed
  File "./RockJiggu/urls.py", line 18, in <module>
    from chatbot import urls as chatbot_url
  File "./chatbot/urls.py", line 2, in <module>
    from . import views
  File "./chatbot/views.py", line 19
    returns self_introduce()
                         ^
SyntaxError: invalid syntax
[pid: 19556|app: 0|req: 27/27] 5.238.234.18 () {34 vars in 476 bytes} [Wed Oct 23 19:51:55 2019] GET / => generated 109323 bytes in 54 msecs (HTTP/1.1 500) 4 headers in 130 bytes (2 switches on core 0)
Internal Server Error: /
Traceback (most recent call last):
  File "/home/ubuntu/RockJiggu/venv/lib/python3.6/site-packages/django/core/handlers/exception.py", line 34, in inner
    response = get_response(request)
  File "/home/ubuntu/RockJiggu/venv/lib/python3.6/site-packages/django/core/handlers/base.py", line 100, in _get_response
    resolver_match = resolver.resolve(request.path_info)
  File "/home/ubuntu/RockJiggu/venv/lib/python3.6/site-packages/django/urls/resolvers.py", line 536, in resolve
    for pattern in self.url_patterns:
  File "/home/ubuntu/RockJiggu/venv/lib/python3.6/site-packages/django/utils/functional.py", line 80, in __get__
    res = instance.__dict__[self.name] = self.func(instance)
  File "/home/ubuntu/RockJiggu/venv/lib/python3.6/site-packages/django/urls/resolvers.py", line 584, in url_patterns
    patterns = getattr(self.urlconf_module, "urlpatterns", self.urlconf_module)
  File "/home/ubuntu/RockJiggu/venv/lib/python3.6/site-packages/django/utils/functional.py", line 80, in __get__
    res = instance.__dict__[self.name] = self.func(instance)
  File "/home/ubuntu/RockJiggu/venv/lib/python3.6/site-packages/django/urls/resolvers.py", line 577, in urlconf_module
    return import_module(self.urlconf_name)
  File "/home/ubuntu/RockJiggu/venv/lib/python3.6/importlib/__init__.py", line 126, in import_module
    return _bootstrap._gcd_import(name[level:], package, level)
  File "<frozen importlib._bootstrap>", line 994, in _gcd_import
  File "<frozen importlib._bootstrap>", line 971, in _find_and_load
  File "<frozen importlib._bootstrap>", line 955, in _find_and_load_unlocked
  File "<frozen importlib._bootstrap>", line 665, in _load_unlocked
  File "<frozen importlib._bootstrap_external>", line 678, in exec_module
  File "<frozen importlib._bootstrap>", line 219, in _call_with_frames_removed
  File "./RockJiggu/urls.py", line 18, in <module>
    from chatbot import urls as chatbot_url
  File "./chatbot/urls.py", line 2, in <module>
    from . import views
  File "./chatbot/views.py", line 19
    returns self_introduce()
                         ^
SyntaxError: invalid syntax
[pid: 19556|app: 0|req: 28/28] 78.171.195.61 () {32 vars in 444 bytes} [Wed Oct 23 20:19:49 2019] GET / => generated 109187 bytes in 51 msecs (HTTP/1.1 500) 4 headers in 130 bytes (2 switches on core 0)
Internal Server Error: /
Traceback (most recent call last):
  File "/home/ubuntu/RockJiggu/venv/lib/python3.6/site-packages/django/core/handlers/exception.py", line 34, in inner
    response = get_response(request)
  File "/home/ubuntu/RockJiggu/venv/lib/python3.6/site-packages/django/core/handlers/base.py", line 100, in _get_response
    resolver_match = resolver.resolve(request.path_info)
  File "/home/ubuntu/RockJiggu/venv/lib/python3.6/site-packages/django/urls/resolvers.py", line 536, in resolve
    for pattern in self.url_patterns:
  File "/home/ubuntu/RockJiggu/venv/lib/python3.6/site-packages/django/utils/functional.py", line 80, in __get__
    res = instance.__dict__[self.name] = self.func(instance)
  File "/home/ubuntu/RockJiggu/venv/lib/python3.6/site-packages/django/urls/resolvers.py", line 584, in url_patterns
    patterns = getattr(self.urlconf_module, "urlpatterns", self.urlconf_module)
  File "/home/ubuntu/RockJiggu/venv/lib/python3.6/site-packages/django/utils/functional.py", line 80, in __get__
    res = instance.__dict__[self.name] = self.func(instance)
  File "/home/ubuntu/RockJiggu/venv/lib/python3.6/site-packages/django/urls/resolvers.py", line 577, in urlconf_module
    return import_module(self.urlconf_name)
  File "/home/ubuntu/RockJiggu/venv/lib/python3.6/importlib/__init__.py", line 126, in import_module
    return _bootstrap._gcd_import(name[level:], package, level)
  File "<frozen importlib._bootstrap>", line 994, in _gcd_import
  File "<frozen importlib._bootstrap>", line 971, in _find_and_load
  File "<frozen importlib._bootstrap>", line 955, in _find_and_load_unlocked
  File "<frozen importlib._bootstrap>", line 665, in _load_unlocked
  File "<frozen importlib._bootstrap_external>", line 678, in exec_module
  File "<frozen importlib._bootstrap>", line 219, in _call_with_frames_removed
  File "./RockJiggu/urls.py", line 18, in <module>
    from chatbot import urls as chatbot_url
  File "./chatbot/urls.py", line 2, in <module>
    from . import views
  File "./chatbot/views.py", line 19
    returns self_introduce()
                         ^
SyntaxError: invalid syntax
[pid: 19556|app: 0|req: 29/29] 101.255.76.26 () {32 vars in 451 bytes} [Wed Oct 23 20:38:11 2019] GET / => generated 109194 bytes in 49 msecs (HTTP/1.1 500) 4 headers in 130 bytes (2 switches on core 0)
Internal Server Error: /editBlackAndWhiteList
Traceback (most recent call last):
  File "/home/ubuntu/RockJiggu/venv/lib/python3.6/site-packages/django/core/handlers/exception.py", line 34, in inner
    response = get_response(request)
  File "/home/ubuntu/RockJiggu/venv/lib/python3.6/site-packages/django/utils/deprecation.py", line 93, in __call__
    response = self.process_request(request)
  File "/home/ubuntu/RockJiggu/venv/lib/python3.6/site-packages/django/middleware/common.py", line 52, in process_request
    if self.should_redirect_with_slash(request):
  File "/home/ubuntu/RockJiggu/venv/lib/python3.6/site-packages/django/middleware/common.py", line 70, in should_redirect_with_slash
    not is_valid_path(request.path_info, urlconf) and
  File "/home/ubuntu/RockJiggu/venv/lib/python3.6/site-packages/django/urls/base.py", line 157, in is_valid_path
    resolve(path, urlconf)
  File "/home/ubuntu/RockJiggu/venv/lib/python3.6/site-packages/django/urls/base.py", line 24, in resolve
    return get_resolver(urlconf).resolve(path)
  File "/home/ubuntu/RockJiggu/venv/lib/python3.6/site-packages/django/urls/resolvers.py", line 536, in resolve
    for pattern in self.url_patterns:
  File "/home/ubuntu/RockJiggu/venv/lib/python3.6/site-packages/django/utils/functional.py", line 80, in __get__
    res = instance.__dict__[self.name] = self.func(instance)
  File "/home/ubuntu/RockJiggu/venv/lib/python3.6/site-packages/django/urls/resolvers.py", line 584, in url_patterns
    patterns = getattr(self.urlconf_module, "urlpatterns", self.urlconf_module)
  File "/home/ubuntu/RockJiggu/venv/lib/python3.6/site-packages/django/utils/functional.py", line 80, in __get__
    res = instance.__dict__[self.name] = self.func(instance)
  File "/home/ubuntu/RockJiggu/venv/lib/python3.6/site-packages/django/urls/resolvers.py", line 577, in urlconf_module
    return import_module(self.urlconf_name)
  File "/home/ubuntu/RockJiggu/venv/lib/python3.6/importlib/__init__.py", line 126, in import_module
    return _bootstrap._gcd_import(name[level:], package, level)
  File "<frozen importlib._bootstrap>", line 994, in _gcd_import
  File "<frozen importlib._bootstrap>", line 971, in _find_and_load
  File "<frozen importlib._bootstrap>", line 955, in _find_and_load_unlocked
  File "<frozen importlib._bootstrap>", line 665, in _load_unlocked
  File "<frozen importlib._bootstrap_external>", line 678, in exec_module
  File "<frozen importlib._bootstrap>", line 219, in _call_with_frames_removed
  File "./RockJiggu/urls.py", line 18, in <module>
    from chatbot import urls as chatbot_url
  File "./chatbot/urls.py", line 2, in <module>
    from . import views
  File "./chatbot/views.py", line 19
    returns self_introduce()
                         ^
SyntaxError: invalid syntax
[pid: 19556|app: 0|req: 30/30] 45.84.185.182 () {46 vars in 644 bytes} [Wed Oct 23 20:38:31 2019] POST /editBlackAndWhiteList => generated 126042 bytes in 58 msecs (HTTP/1.1 500) 1 headers in 63 bytes (1 switches on core 0)
Internal Server Error: /
Traceback (most recent call last):
  File "/home/ubuntu/RockJiggu/venv/lib/python3.6/site-packages/django/core/handlers/exception.py", line 34, in inner
    response = get_response(request)
  File "/home/ubuntu/RockJiggu/venv/lib/python3.6/site-packages/django/core/handlers/base.py", line 100, in _get_response
    resolver_match = resolver.resolve(request.path_info)
  File "/home/ubuntu/RockJiggu/venv/lib/python3.6/site-packages/django/urls/resolvers.py", line 536, in resolve
    for pattern in self.url_patterns:
  File "/home/ubuntu/RockJiggu/venv/lib/python3.6/site-packages/django/utils/functional.py", line 80, in __get__
    res = instance.__dict__[self.name] = self.func(instance)
  File "/home/ubuntu/RockJiggu/venv/lib/python3.6/site-packages/django/urls/resolvers.py", line 584, in url_patterns
    patterns = getattr(self.urlconf_module, "urlpatterns", self.urlconf_module)
  File "/home/ubuntu/RockJiggu/venv/lib/python3.6/site-packages/django/utils/functional.py", line 80, in __get__
    res = instance.__dict__[self.name] = self.func(instance)
  File "/home/ubuntu/RockJiggu/venv/lib/python3.6/site-packages/django/urls/resolvers.py", line 577, in urlconf_module
    return import_module(self.urlconf_name)
  File "/home/ubuntu/RockJiggu/venv/lib/python3.6/importlib/__init__.py", line 126, in import_module
    return _bootstrap._gcd_import(name[level:], package, level)
  File "<frozen importlib._bootstrap>", line 994, in _gcd_import
  File "<frozen importlib._bootstrap>", line 971, in _find_and_load
  File "<frozen importlib._bootstrap>", line 955, in _find_and_load_unlocked
  File "<frozen importlib._bootstrap>", line 665, in _load_unlocked
  File "<frozen importlib._bootstrap_external>", line 678, in exec_module
  File "<frozen importlib._bootstrap>", line 219, in _call_with_frames_removed
  File "./RockJiggu/urls.py", line 18, in <module>
    from chatbot import urls as chatbot_url
  File "./chatbot/urls.py", line 2, in <module>
    from . import views
  File "./chatbot/views.py", line 19
    returns self_introduce()
                         ^
SyntaxError: invalid syntax
[pid: 19556|app: 0|req: 31/31] 200.148.106.77 () {32 vars in 446 bytes} [Wed Oct 23 21:43:43 2019] GET / => generated 109189 bytes in 54 msecs (HTTP/1.1 500) 4 headers in 130 bytes (2 switches on core 0)
Invalid HTTP_HOST header: '_'. The domain name provided is not valid according to RFC 1034/1035.
Bad Request: /
[pid: 19556|app: 0|req: 32/32] 209.17.96.138 () {30 vars in 379 bytes} [Wed Oct 23 22:49:44 2019] GET / => generated 54216 bytes in 32 msecs (HTTP/1.0 400) 1 headers in 53 bytes (2 switches on core 0)
Invalid HTTP_HOST header: '_'. The domain name provided is not valid according to RFC 1034/1035.
Bad Request: /
[pid: 19556|app: 0|req: 33/33] 5.35.147.31 () {26 vars in 259 bytes} [Wed Oct 23 23:55:53 2019] GET / => generated 53874 bytes in 27 msecs (HTTP/1.0 400) 1 headers in 53 bytes (2 switches on core 0)
Internal Server Error: /
Traceback (most recent call last):
  File "/home/ubuntu/RockJiggu/venv/lib/python3.6/site-packages/django/core/handlers/exception.py", line 34, in inner
    response = get_response(request)
  File "/home/ubuntu/RockJiggu/venv/lib/python3.6/site-packages/django/core/handlers/base.py", line 100, in _get_response
    resolver_match = resolver.resolve(request.path_info)
  File "/home/ubuntu/RockJiggu/venv/lib/python3.6/site-packages/django/urls/resolvers.py", line 536, in resolve
    for pattern in self.url_patterns:
  File "/home/ubuntu/RockJiggu/venv/lib/python3.6/site-packages/django/utils/functional.py", line 80, in __get__
    res = instance.__dict__[self.name] = self.func(instance)
  File "/home/ubuntu/RockJiggu/venv/lib/python3.6/site-packages/django/urls/resolvers.py", line 584, in url_patterns
    patterns = getattr(self.urlconf_module, "urlpatterns", self.urlconf_module)
  File "/home/ubuntu/RockJiggu/venv/lib/python3.6/site-packages/django/utils/functional.py", line 80, in __get__
    res = instance.__dict__[self.name] = self.func(instance)
  File "/home/ubuntu/RockJiggu/venv/lib/python3.6/site-packages/django/urls/resolvers.py", line 577, in urlconf_module
    return import_module(self.urlconf_name)
  File "/home/ubuntu/RockJiggu/venv/lib/python3.6/importlib/__init__.py", line 126, in import_module
    return _bootstrap._gcd_import(name[level:], package, level)
  File "<frozen importlib._bootstrap>", line 994, in _gcd_import
  File "<frozen importlib._bootstrap>", line 971, in _find_and_load
  File "<frozen importlib._bootstrap>", line 955, in _find_and_load_unlocked
  File "<frozen importlib._bootstrap>", line 665, in _load_unlocked
  File "<frozen importlib._bootstrap_external>", line 678, in exec_module
  File "<frozen importlib._bootstrap>", line 219, in _call_with_frames_removed
  File "./RockJiggu/urls.py", line 18, in <module>
    from chatbot import urls as chatbot_url
  File "./chatbot/urls.py", line 2, in <module>
    from . import views
  File "./chatbot/views.py", line 19
    returns self_introduce()
                         ^
SyntaxError: invalid syntax
[pid: 19556|app: 0|req: 34/34] 109.161.126.1 () {32 vars in 444 bytes} [Thu Oct 24 01:02:00 2019] GET / => generated 109187 bytes in 50 msecs (HTTP/1.1 500) 4 headers in 130 bytes (2 switches on core 0)
Internal Server Error: /
Traceback (most recent call last):
  File "/home/ubuntu/RockJiggu/venv/lib/python3.6/site-packages/django/core/handlers/exception.py", line 34, in inner
    response = get_response(request)
  File "/home/ubuntu/RockJiggu/venv/lib/python3.6/site-packages/django/core/handlers/base.py", line 100, in _get_response
    resolver_match = resolver.resolve(request.path_info)
  File "/home/ubuntu/RockJiggu/venv/lib/python3.6/site-packages/django/urls/resolvers.py", line 536, in resolve
    for pattern in self.url_patterns:
  File "/home/ubuntu/RockJiggu/venv/lib/python3.6/site-packages/django/utils/functional.py", line 80, in __get__
    res = instance.__dict__[self.name] = self.func(instance)
  File "/home/ubuntu/RockJiggu/venv/lib/python3.6/site-packages/django/urls/resolvers.py", line 584, in url_patterns
    patterns = getattr(self.urlconf_module, "urlpatterns", self.urlconf_module)
  File "/home/ubuntu/RockJiggu/venv/lib/python3.6/site-packages/django/utils/functional.py", line 80, in __get__
    res = instance.__dict__[self.name] = self.func(instance)
  File "/home/ubuntu/RockJiggu/venv/lib/python3.6/site-packages/django/urls/resolvers.py", line 577, in urlconf_module
    return import_module(self.urlconf_name)
  File "/home/ubuntu/RockJiggu/venv/lib/python3.6/importlib/__init__.py", line 126, in import_module
    return _bootstrap._gcd_import(name[level:], package, level)
  File "<frozen importlib._bootstrap>", line 994, in _gcd_import
  File "<frozen importlib._bootstrap>", line 971, in _find_and_load
  File "<frozen importlib._bootstrap>", line 955, in _find_and_load_unlocked
  File "<frozen importlib._bootstrap>", line 665, in _load_unlocked
  File "<frozen importlib._bootstrap_external>", line 678, in exec_module
  File "<frozen importlib._bootstrap>", line 219, in _call_with_frames_removed
  File "./RockJiggu/urls.py", line 18, in <module>
    from chatbot import urls as chatbot_url
  File "./chatbot/urls.py", line 2, in <module>
    from . import views
  File "./chatbot/views.py", line 19
    returns self_introduce()
                         ^
SyntaxError: invalid syntax
[pid: 19556|app: 0|req: 35/35] 2.183.80.145 () {32 vars in 444 bytes} [Thu Oct 24 01:11:22 2019] GET / => generated 109187 bytes in 56 msecs (HTTP/1.1 500) 4 headers in 130 bytes (1 switches on core 0)
Internal Server Error: /
Traceback (most recent call last):
  File "/home/ubuntu/RockJiggu/venv/lib/python3.6/site-packages/django/core/handlers/exception.py", line 34, in inner
    response = get_response(request)
  File "/home/ubuntu/RockJiggu/venv/lib/python3.6/site-packages/django/core/handlers/base.py", line 100, in _get_response
    resolver_match = resolver.resolve(request.path_info)
  File "/home/ubuntu/RockJiggu/venv/lib/python3.6/site-packages/django/urls/resolvers.py", line 536, in resolve
    for pattern in self.url_patterns:
  File "/home/ubuntu/RockJiggu/venv/lib/python3.6/site-packages/django/utils/functional.py", line 80, in __get__
    res = instance.__dict__[self.name] = self.func(instance)
  File "/home/ubuntu/RockJiggu/venv/lib/python3.6/site-packages/django/urls/resolvers.py", line 584, in url_patterns
    patterns = getattr(self.urlconf_module, "urlpatterns", self.urlconf_module)
  File "/home/ubuntu/RockJiggu/venv/lib/python3.6/site-packages/django/utils/functional.py", line 80, in __get__
    res = instance.__dict__[self.name] = self.func(instance)
  File "/home/ubuntu/RockJiggu/venv/lib/python3.6/site-packages/django/urls/resolvers.py", line 577, in urlconf_module
    return import_module(self.urlconf_name)
  File "/home/ubuntu/RockJiggu/venv/lib/python3.6/importlib/__init__.py", line 126, in import_module
    return _bootstrap._gcd_import(name[level:], package, level)
  File "<frozen importlib._bootstrap>", line 994, in _gcd_import
  File "<frozen importlib._bootstrap>", line 971, in _find_and_load
  File "<frozen importlib._bootstrap>", line 955, in _find_and_load_unlocked
  File "<frozen importlib._bootstrap>", line 665, in _load_unlocked
  File "<frozen importlib._bootstrap_external>", line 678, in exec_module
  File "<frozen importlib._bootstrap>", line 219, in _call_with_frames_removed
  File "./RockJiggu/urls.py", line 18, in <module>
    from chatbot import urls as chatbot_url
  File "./chatbot/urls.py", line 2, in <module>
    from . import views
  File "./chatbot/views.py", line 19
    returns self_introduce()
                         ^
SyntaxError: invalid syntax
[pid: 19556|app: 0|req: 36/36] 189.69.254.146 () {32 vars in 452 bytes} [Thu Oct 24 01:12:08 2019] GET / => generated 109195 bytes in 51 msecs (HTTP/1.1 500) 4 headers in 130 bytes (1 switches on core 0)
Internal Server Error: /
Traceback (most recent call last):
  File "/home/ubuntu/RockJiggu/venv/lib/python3.6/site-packages/django/core/handlers/exception.py", line 34, in inner
    response = get_response(request)
  File "/home/ubuntu/RockJiggu/venv/lib/python3.6/site-packages/django/core/handlers/base.py", line 100, in _get_response
    resolver_match = resolver.resolve(request.path_info)
  File "/home/ubuntu/RockJiggu/venv/lib/python3.6/site-packages/django/urls/resolvers.py", line 536, in resolve
    for pattern in self.url_patterns:
  File "/home/ubuntu/RockJiggu/venv/lib/python3.6/site-packages/django/utils/functional.py", line 80, in __get__
    res = instance.__dict__[self.name] = self.func(instance)
  File "/home/ubuntu/RockJiggu/venv/lib/python3.6/site-packages/django/urls/resolvers.py", line 584, in url_patterns
    patterns = getattr(self.urlconf_module, "urlpatterns", self.urlconf_module)
  File "/home/ubuntu/RockJiggu/venv/lib/python3.6/site-packages/django/utils/functional.py", line 80, in __get__
    res = instance.__dict__[self.name] = self.func(instance)
  File "/home/ubuntu/RockJiggu/venv/lib/python3.6/site-packages/django/urls/resolvers.py", line 577, in urlconf_module
    return import_module(self.urlconf_name)
  File "/home/ubuntu/RockJiggu/venv/lib/python3.6/importlib/__init__.py", line 126, in import_module
    return _bootstrap._gcd_import(name[level:], package, level)
  File "<frozen importlib._bootstrap>", line 994, in _gcd_import
  File "<frozen importlib._bootstrap>", line 971, in _find_and_load
  File "<frozen importlib._bootstrap>", line 955, in _find_and_load_unlocked
  File "<frozen importlib._bootstrap>", line 665, in _load_unlocked
  File "<frozen importlib._bootstrap_external>", line 678, in exec_module
  File "<frozen importlib._bootstrap>", line 219, in _call_with_frames_removed
  File "./RockJiggu/urls.py", line 18, in <module>
    from chatbot import urls as chatbot_url
  File "./chatbot/urls.py", line 2, in <module>
    from . import views
  File "./chatbot/views.py", line 19
    returns self_introduce()
                         ^
SyntaxError: invalid syntax
[pid: 19556|app: 0|req: 37/37] 179.110.235.183 () {32 vars in 447 bytes} [Thu Oct 24 01:21:36 2019] GET / => generated 109190 bytes in 52 msecs (HTTP/1.1 500) 4 headers in 130 bytes (2 switches on core 0)
Internal Server Error: /
Traceback (most recent call last):
  File "/home/ubuntu/RockJiggu/venv/lib/python3.6/site-packages/django/core/handlers/exception.py", line 34, in inner
    response = get_response(request)
  File "/home/ubuntu/RockJiggu/venv/lib/python3.6/site-packages/django/core/handlers/base.py", line 100, in _get_response
    resolver_match = resolver.resolve(request.path_info)
  File "/home/ubuntu/RockJiggu/venv/lib/python3.6/site-packages/django/urls/resolvers.py", line 536, in resolve
    for pattern in self.url_patterns:
  File "/home/ubuntu/RockJiggu/venv/lib/python3.6/site-packages/django/utils/functional.py", line 80, in __get__
    res = instance.__dict__[self.name] = self.func(instance)
  File "/home/ubuntu/RockJiggu/venv/lib/python3.6/site-packages/django/urls/resolvers.py", line 584, in url_patterns
    patterns = getattr(self.urlconf_module, "urlpatterns", self.urlconf_module)
  File "/home/ubuntu/RockJiggu/venv/lib/python3.6/site-packages/django/utils/functional.py", line 80, in __get__
    res = instance.__dict__[self.name] = self.func(instance)
  File "/home/ubuntu/RockJiggu/venv/lib/python3.6/site-packages/django/urls/resolvers.py", line 577, in urlconf_module
    return import_module(self.urlconf_name)
  File "/home/ubuntu/RockJiggu/venv/lib/python3.6/importlib/__init__.py", line 126, in import_module
    return _bootstrap._gcd_import(name[level:], package, level)
  File "<frozen importlib._bootstrap>", line 994, in _gcd_import
  File "<frozen importlib._bootstrap>", line 971, in _find_and_load
  File "<frozen importlib._bootstrap>", line 955, in _find_and_load_unlocked
  File "<frozen importlib._bootstrap>", line 665, in _load_unlocked
  File "<frozen importlib._bootstrap_external>", line 678, in exec_module
  File "<frozen importlib._bootstrap>", line 219, in _call_with_frames_removed
  File "./RockJiggu/urls.py", line 18, in <module>
    from chatbot import urls as chatbot_url
  File "./chatbot/urls.py", line 2, in <module>
    from . import views
  File "./chatbot/views.py", line 19
    returns self_introduce()
                         ^
SyntaxError: invalid syntax
[pid: 19556|app: 0|req: 38/38] 201.238.154.246 () {30 vars in 419 bytes} [Thu Oct 24 01:39:33 2019] GET / => generated 109052 bytes in 50 msecs (HTTP/1.1 500) 4 headers in 130 bytes (2 switches on core 0)
Internal Server Error: /
Traceback (most recent call last):
  File "/home/ubuntu/RockJiggu/venv/lib/python3.6/site-packages/django/core/handlers/exception.py", line 34, in inner
    response = get_response(request)
  File "/home/ubuntu/RockJiggu/venv/lib/python3.6/site-packages/django/core/handlers/base.py", line 100, in _get_response
    resolver_match = resolver.resolve(request.path_info)
  File "/home/ubuntu/RockJiggu/venv/lib/python3.6/site-packages/django/urls/resolvers.py", line 536, in resolve
    for pattern in self.url_patterns:
  File "/home/ubuntu/RockJiggu/venv/lib/python3.6/site-packages/django/utils/functional.py", line 80, in __get__
    res = instance.__dict__[self.name] = self.func(instance)
  File "/home/ubuntu/RockJiggu/venv/lib/python3.6/site-packages/django/urls/resolvers.py", line 584, in url_patterns
    patterns = getattr(self.urlconf_module, "urlpatterns", self.urlconf_module)
  File "/home/ubuntu/RockJiggu/venv/lib/python3.6/site-packages/django/utils/functional.py", line 80, in __get__
    res = instance.__dict__[self.name] = self.func(instance)
  File "/home/ubuntu/RockJiggu/venv/lib/python3.6/site-packages/django/urls/resolvers.py", line 577, in urlconf_module
    return import_module(self.urlconf_name)
  File "/home/ubuntu/RockJiggu/venv/lib/python3.6/importlib/__init__.py", line 126, in import_module
    return _bootstrap._gcd_import(name[level:], package, level)
  File "<frozen importlib._bootstrap>", line 994, in _gcd_import
  File "<frozen importlib._bootstrap>", line 971, in _find_and_load
  File "<frozen importlib._bootstrap>", line 955, in _find_and_load_unlocked
  File "<frozen importlib._bootstrap>", line 665, in _load_unlocked
  File "<frozen importlib._bootstrap_external>", line 678, in exec_module
  File "<frozen importlib._bootstrap>", line 219, in _call_with_frames_removed
  File "./RockJiggu/urls.py", line 18, in <module>
    from chatbot import urls as chatbot_url
  File "./chatbot/urls.py", line 2, in <module>
    from . import views
  File "./chatbot/views.py", line 19
    returns self_introduce()
                         ^
SyntaxError: invalid syntax
[pid: 19556|app: 0|req: 39/39] 186.219.219.5 () {32 vars in 444 bytes} [Thu Oct 24 01:50:45 2019] GET / => generated 109187 bytes in 51 msecs (HTTP/1.1 500) 4 headers in 130 bytes (2 switches on core 0)
Internal Server Error: /
Traceback (most recent call last):
  File "/home/ubuntu/RockJiggu/venv/lib/python3.6/site-packages/django/core/handlers/exception.py", line 34, in inner
    response = get_response(request)
  File "/home/ubuntu/RockJiggu/venv/lib/python3.6/site-packages/django/core/handlers/base.py", line 100, in _get_response
    resolver_match = resolver.resolve(request.path_info)
  File "/home/ubuntu/RockJiggu/venv/lib/python3.6/site-packages/django/urls/resolvers.py", line 536, in resolve
    for pattern in self.url_patterns:
  File "/home/ubuntu/RockJiggu/venv/lib/python3.6/site-packages/django/utils/functional.py", line 80, in __get__
    res = instance.__dict__[self.name] = self.func(instance)
  File "/home/ubuntu/RockJiggu/venv/lib/python3.6/site-packages/django/urls/resolvers.py", line 584, in url_patterns
    patterns = getattr(self.urlconf_module, "urlpatterns", self.urlconf_module)
  File "/home/ubuntu/RockJiggu/venv/lib/python3.6/site-packages/django/utils/functional.py", line 80, in __get__
    res = instance.__dict__[self.name] = self.func(instance)
  File "/home/ubuntu/RockJiggu/venv/lib/python3.6/site-packages/django/urls/resolvers.py", line 577, in urlconf_module
    return import_module(self.urlconf_name)
  File "/home/ubuntu/RockJiggu/venv/lib/python3.6/importlib/__init__.py", line 126, in import_module
    return _bootstrap._gcd_import(name[level:], package, level)
  File "<frozen importlib._bootstrap>", line 994, in _gcd_import
  File "<frozen importlib._bootstrap>", line 971, in _find_and_load
  File "<frozen importlib._bootstrap>", line 955, in _find_and_load_unlocked
  File "<frozen importlib._bootstrap>", line 665, in _load_unlocked
  File "<frozen importlib._bootstrap_external>", line 678, in exec_module
  File "<frozen importlib._bootstrap>", line 219, in _call_with_frames_removed
  File "./RockJiggu/urls.py", line 18, in <module>
    from chatbot import urls as chatbot_url
  File "./chatbot/urls.py", line 2, in <module>
    from . import views
  File "./chatbot/views.py", line 19
    returns self_introduce()
                         ^
SyntaxError: invalid syntax
[pid: 19556|app: 0|req: 40/40] 177.11.136.68 () {32 vars in 444 bytes} [Thu Oct 24 03:15:18 2019] GET / => generated 109187 bytes in 46 msecs (HTTP/1.1 500) 4 headers in 130 bytes (2 switches on core 0)
Internal Server Error: /
Traceback (most recent call last):
  File "/home/ubuntu/RockJiggu/venv/lib/python3.6/site-packages/django/core/handlers/exception.py", line 34, in inner
    response = get_response(request)
  File "/home/ubuntu/RockJiggu/venv/lib/python3.6/site-packages/django/core/handlers/base.py", line 100, in _get_response
    resolver_match = resolver.resolve(request.path_info)
  File "/home/ubuntu/RockJiggu/venv/lib/python3.6/site-packages/django/urls/resolvers.py", line 536, in resolve
    for pattern in self.url_patterns:
  File "/home/ubuntu/RockJiggu/venv/lib/python3.6/site-packages/django/utils/functional.py", line 80, in __get__
    res = instance.__dict__[self.name] = self.func(instance)
  File "/home/ubuntu/RockJiggu/venv/lib/python3.6/site-packages/django/urls/resolvers.py", line 584, in url_patterns
    patterns = getattr(self.urlconf_module, "urlpatterns", self.urlconf_module)
  File "/home/ubuntu/RockJiggu/venv/lib/python3.6/site-packages/django/utils/functional.py", line 80, in __get__
    res = instance.__dict__[self.name] = self.func(instance)
  File "/home/ubuntu/RockJiggu/venv/lib/python3.6/site-packages/django/urls/resolvers.py", line 577, in urlconf_module
    return import_module(self.urlconf_name)
  File "/home/ubuntu/RockJiggu/venv/lib/python3.6/importlib/__init__.py", line 126, in import_module
    return _bootstrap._gcd_import(name[level:], package, level)
  File "<frozen importlib._bootstrap>", line 994, in _gcd_import
  File "<frozen importlib._bootstrap>", line 971, in _find_and_load
  File "<frozen importlib._bootstrap>", line 955, in _find_and_load_unlocked
  File "<frozen importlib._bootstrap>", line 665, in _load_unlocked
  File "<frozen importlib._bootstrap_external>", line 678, in exec_module
  File "<frozen importlib._bootstrap>", line 219, in _call_with_frames_removed
  File "./RockJiggu/urls.py", line 18, in <module>
    from chatbot import urls as chatbot_url
  File "./chatbot/urls.py", line 2, in <module>
    from . import views
  File "./chatbot/views.py", line 19
    returns self_introduce()
                         ^
SyntaxError: invalid syntax
[pid: 19556|app: 0|req: 41/41] 88.249.253.156 () {32 vars in 446 bytes} [Thu Oct 24 05:07:19 2019] GET / => generated 109189 bytes in 52 msecs (HTTP/1.1 500) 4 headers in 130 bytes (2 switches on core 0)
Invalid HTTP_HOST header: '_'. The domain name provided is not valid according to RFC 1034/1035.
Bad Request: /
[pid: 19556|app: 0|req: 42/42] 91.126.88.117 () {26 vars in 261 bytes} [Thu Oct 24 05:28:54 2019] GET / => generated 53876 bytes in 28 msecs (HTTP/1.0 400) 1 headers in 53 bytes (2 switches on core 0)
Internal Server Error: /
Traceback (most recent call last):
  File "/home/ubuntu/RockJiggu/venv/lib/python3.6/site-packages/django/core/handlers/exception.py", line 34, in inner
    response = get_response(request)
  File "/home/ubuntu/RockJiggu/venv/lib/python3.6/site-packages/django/core/handlers/base.py", line 100, in _get_response
    resolver_match = resolver.resolve(request.path_info)
  File "/home/ubuntu/RockJiggu/venv/lib/python3.6/site-packages/django/urls/resolvers.py", line 536, in resolve
    for pattern in self.url_patterns:
  File "/home/ubuntu/RockJiggu/venv/lib/python3.6/site-packages/django/utils/functional.py", line 80, in __get__
    res = instance.__dict__[self.name] = self.func(instance)
  File "/home/ubuntu/RockJiggu/venv/lib/python3.6/site-packages/django/urls/resolvers.py", line 584, in url_patterns
    patterns = getattr(self.urlconf_module, "urlpatterns", self.urlconf_module)
  File "/home/ubuntu/RockJiggu/venv/lib/python3.6/site-packages/django/utils/functional.py", line 80, in __get__
    res = instance.__dict__[self.name] = self.func(instance)
  File "/home/ubuntu/RockJiggu/venv/lib/python3.6/site-packages/django/urls/resolvers.py", line 577, in urlconf_module
    return import_module(self.urlconf_name)
  File "/home/ubuntu/RockJiggu/venv/lib/python3.6/importlib/__init__.py", line 126, in import_module
    return _bootstrap._gcd_import(name[level:], package, level)
  File "<frozen importlib._bootstrap>", line 994, in _gcd_import
  File "<frozen importlib._bootstrap>", line 971, in _find_and_load
  File "<frozen importlib._bootstrap>", line 955, in _find_and_load_unlocked
  File "<frozen importlib._bootstrap>", line 665, in _load_unlocked
  File "<frozen importlib._bootstrap_external>", line 678, in exec_module
  File "<frozen importlib._bootstrap>", line 219, in _call_with_frames_removed
  File "./RockJiggu/urls.py", line 18, in <module>
    from chatbot import urls as chatbot_url
  File "./chatbot/urls.py", line 2, in <module>
    from . import views
  File "./chatbot/views.py", line 19
    returns self_introduce()
                         ^
SyntaxError: invalid syntax
[pid: 19556|app: 0|req: 43/43] 110.13.194.132 () {44 vars in 775 bytes} [Thu Oct 24 06:48:32 2019] GET / => generated 110136 bytes in 54 msecs (HTTP/1.1 500) 4 headers in 130 bytes (2 switches on core 0)
Internal Server Error: /favicon.ico
Traceback (most recent call last):
  File "/home/ubuntu/RockJiggu/venv/lib/python3.6/site-packages/django/core/handlers/exception.py", line 34, in inner
    response = get_response(request)
  File "/home/ubuntu/RockJiggu/venv/lib/python3.6/site-packages/django/utils/deprecation.py", line 93, in __call__
    response = self.process_request(request)
  File "/home/ubuntu/RockJiggu/venv/lib/python3.6/site-packages/django/middleware/common.py", line 52, in process_request
    if self.should_redirect_with_slash(request):
  File "/home/ubuntu/RockJiggu/venv/lib/python3.6/site-packages/django/middleware/common.py", line 70, in should_redirect_with_slash
    not is_valid_path(request.path_info, urlconf) and
  File "/home/ubuntu/RockJiggu/venv/lib/python3.6/site-packages/django/urls/base.py", line 157, in is_valid_path
    resolve(path, urlconf)
  File "/home/ubuntu/RockJiggu/venv/lib/python3.6/site-packages/django/urls/base.py", line 24, in resolve
    return get_resolver(urlconf).resolve(path)
  File "/home/ubuntu/RockJiggu/venv/lib/python3.6/site-packages/django/urls/resolvers.py", line 536, in resolve
    for pattern in self.url_patterns:
  File "/home/ubuntu/RockJiggu/venv/lib/python3.6/site-packages/django/utils/functional.py", line 80, in __get__
    res = instance.__dict__[self.name] = self.func(instance)
  File "/home/ubuntu/RockJiggu/venv/lib/python3.6/site-packages/django/urls/resolvers.py", line 584, in url_patterns
    patterns = getattr(self.urlconf_module, "urlpatterns", self.urlconf_module)
  File "/home/ubuntu/RockJiggu/venv/lib/python3.6/site-packages/django/utils/functional.py", line 80, in __get__
    res = instance.__dict__[self.name] = self.func(instance)
  File "/home/ubuntu/RockJiggu/venv/lib/python3.6/site-packages/django/urls/resolvers.py", line 577, in urlconf_module
    return import_module(self.urlconf_name)
  File "/home/ubuntu/RockJiggu/venv/lib/python3.6/importlib/__init__.py", line 126, in import_module
    return _bootstrap._gcd_import(name[level:], package, level)
  File "<frozen importlib._bootstrap>", line 994, in _gcd_import
  File "<frozen importlib._bootstrap>", line 971, in _find_and_load
  File "<frozen importlib._bootstrap>", line 955, in _find_and_load_unlocked
  File "<frozen importlib._bootstrap>", line 665, in _load_unlocked
  File "<frozen importlib._bootstrap_external>", line 678, in exec_module
  File "<frozen importlib._bootstrap>", line 219, in _call_with_frames_removed
  File "./RockJiggu/urls.py", line 18, in <module>
    from chatbot import urls as chatbot_url
  File "./chatbot/urls.py", line 2, in <module>
    from . import views
  File "./chatbot/views.py", line 19
    returns self_introduce()
                         ^
SyntaxError: invalid syntax
[pid: 19556|app: 0|req: 44/44] 110.13.194.132 () {44 vars in 721 bytes} [Thu Oct 24 06:48:34 2019] GET /favicon.ico => generated 125873 bytes in 60 msecs (HTTP/1.1 500) 1 headers in 63 bytes (1 switches on core 0)
Internal Server Error: /
Traceback (most recent call last):
  File "/home/ubuntu/RockJiggu/venv/lib/python3.6/site-packages/django/core/handlers/exception.py", line 34, in inner
    response = get_response(request)
  File "/home/ubuntu/RockJiggu/venv/lib/python3.6/site-packages/django/core/handlers/base.py", line 115, in _get_response
    response = self.process_exception_by_middleware(e, request)
  File "/home/ubuntu/RockJiggu/venv/lib/python3.6/site-packages/django/core/handlers/base.py", line 113, in _get_response
    response = wrapped_callback(request, *callback_args, **callback_kwargs)
  File "./RockJiggu/views.py", line 4, in home
    return render(request, 'index.html')
  File "/home/ubuntu/RockJiggu/venv/lib/python3.6/site-packages/django/shortcuts.py", line 36, in render
    content = loader.render_to_string(template_name, context, request, using=using)
  File "/home/ubuntu/RockJiggu/venv/lib/python3.6/site-packages/django/template/loader.py", line 61, in render_to_string
    template = get_template(template_name, using=using)
  File "/home/ubuntu/RockJiggu/venv/lib/python3.6/site-packages/django/template/loader.py", line 19, in get_template
    raise TemplateDoesNotExist(template_name, chain=chain)
django.template.exceptions.TemplateDoesNotExist: index.html
[pid: 19556|app: 0|req: 45/45] 110.13.194.132 () {40 vars in 722 bytes} [Thu Oct 24 07:38:14 2019] GET / => generated 69728 bytes in 47 msecs (HTTP/1.1 500) 4 headers in 129 bytes (1 switches on core 0)
Not Found: /favicon.ico
[pid: 19556|app: 0|req: 46/46] 110.13.194.132 () {40 vars in 668 bytes} [Thu Oct 24 07:38:16 2019] GET /favicon.ico => generated 2196 bytes in 4 msecs (HTTP/1.1 404) 3 headers in 102 bytes (1 switches on core 0)
Internal Server Error: /
Traceback (most recent call last):
  File "/home/ubuntu/RockJiggu/venv/lib/python3.6/site-packages/django/core/handlers/exception.py", line 34, in inner
    response = get_response(request)
  File "/home/ubuntu/RockJiggu/venv/lib/python3.6/site-packages/django/core/handlers/base.py", line 115, in _get_response
    response = self.process_exception_by_middleware(e, request)
  File "/home/ubuntu/RockJiggu/venv/lib/python3.6/site-packages/django/core/handlers/base.py", line 113, in _get_response
    response = wrapped_callback(request, *callback_args, **callback_kwargs)
  File "./RockJiggu/views.py", line 4, in home
    return render(request, 'index.html')
  File "/home/ubuntu/RockJiggu/venv/lib/python3.6/site-packages/django/shortcuts.py", line 36, in render
    content = loader.render_to_string(template_name, context, request, using=using)
  File "/home/ubuntu/RockJiggu/venv/lib/python3.6/site-packages/django/template/loader.py", line 61, in render_to_string
    template = get_template(template_name, using=using)
  File "/home/ubuntu/RockJiggu/venv/lib/python3.6/site-packages/django/template/loader.py", line 19, in get_template
    raise TemplateDoesNotExist(template_name, chain=chain)
django.template.exceptions.TemplateDoesNotExist: index.html
[pid: 19556|app: 0|req: 47/47] 110.13.194.132 () {42 vars in 753 bytes} [Thu Oct 24 07:41:13 2019] GET / => generated 69863 bytes in 42 msecs (HTTP/1.1 500) 4 headers in 129 bytes (2 switches on core 0)
Internal Server Error: /
Traceback (most recent call last):
  File "/home/ubuntu/RockJiggu/venv/lib/python3.6/site-packages/django/core/handlers/exception.py", line 34, in inner
    response = get_response(request)
  File "/home/ubuntu/RockJiggu/venv/lib/python3.6/site-packages/django/core/handlers/base.py", line 115, in _get_response
    response = self.process_exception_by_middleware(e, request)
  File "/home/ubuntu/RockJiggu/venv/lib/python3.6/site-packages/django/core/handlers/base.py", line 113, in _get_response
    response = wrapped_callback(request, *callback_args, **callback_kwargs)
  File "./RockJiggu/views.py", line 4, in home
    return render(request, 'index.html')
  File "/home/ubuntu/RockJiggu/venv/lib/python3.6/site-packages/django/shortcuts.py", line 36, in render
    content = loader.render_to_string(template_name, context, request, using=using)
  File "/home/ubuntu/RockJiggu/venv/lib/python3.6/site-packages/django/template/loader.py", line 61, in render_to_string
    template = get_template(template_name, using=using)
  File "/home/ubuntu/RockJiggu/venv/lib/python3.6/site-packages/django/template/loader.py", line 19, in get_template
    raise TemplateDoesNotExist(template_name, chain=chain)
django.template.exceptions.TemplateDoesNotExist: index.html
[pid: 19556|app: 0|req: 48/48] 110.13.194.132 () {42 vars in 753 bytes} [Thu Oct 24 07:41:16 2019] GET / => generated 69863 bytes in 31 msecs (HTTP/1.1 500) 4 headers in 129 bytes (1 switches on core 0)
Not Found: /home
[pid: 19556|app: 0|req: 49/49] 110.13.194.132 () {40 vars in 730 bytes} [Thu Oct 24 07:41:21 2019] GET /home => generated 2175 bytes in 3 msecs (HTTP/1.1 404) 3 headers in 102 bytes (1 switches on core 0)
Internal Server Error: /
Traceback (most recent call last):
  File "/home/ubuntu/RockJiggu/venv/lib/python3.6/site-packages/django/core/handlers/exception.py", line 34, in inner
    response = get_response(request)
  File "/home/ubuntu/RockJiggu/venv/lib/python3.6/site-packages/django/core/handlers/base.py", line 115, in _get_response
    response = self.process_exception_by_middleware(e, request)
  File "/home/ubuntu/RockJiggu/venv/lib/python3.6/site-packages/django/core/handlers/base.py", line 113, in _get_response
    response = wrapped_callback(request, *callback_args, **callback_kwargs)
  File "./RockJiggu/views.py", line 4, in home
    return render(request, 'index.html')
  File "/home/ubuntu/RockJiggu/venv/lib/python3.6/site-packages/django/shortcuts.py", line 36, in render
    content = loader.render_to_string(template_name, context, request, using=using)
  File "/home/ubuntu/RockJiggu/venv/lib/python3.6/site-packages/django/template/loader.py", line 61, in render_to_string
    template = get_template(template_name, using=using)
  File "/home/ubuntu/RockJiggu/venv/lib/python3.6/site-packages/django/template/loader.py", line 19, in get_template
    raise TemplateDoesNotExist(template_name, chain=chain)
django.template.exceptions.TemplateDoesNotExist: index.html
[pid: 19556|app: 0|req: 50/50] 110.13.194.132 () {40 vars in 722 bytes} [Thu Oct 24 07:41:33 2019] GET / => generated 69728 bytes in 34 msecs (HTTP/1.1 500) 4 headers in 129 bytes (1 switches on core 0)
Internal Server Error: /
Traceback (most recent call last):
  File "/home/ubuntu/RockJiggu/venv/lib/python3.6/site-packages/django/core/handlers/exception.py", line 34, in inner
    response = get_response(request)
  File "/home/ubuntu/RockJiggu/venv/lib/python3.6/site-packages/django/core/handlers/base.py", line 115, in _get_response
    response = self.process_exception_by_middleware(e, request)
  File "/home/ubuntu/RockJiggu/venv/lib/python3.6/site-packages/django/core/handlers/base.py", line 113, in _get_response
    response = wrapped_callback(request, *callback_args, **callback_kwargs)
  File "./RockJiggu/views.py", line 4, in home
    return render(request, 'index.html')
  File "/home/ubuntu/RockJiggu/venv/lib/python3.6/site-packages/django/shortcuts.py", line 36, in render
    content = loader.render_to_string(template_name, context, request, using=using)
  File "/home/ubuntu/RockJiggu/venv/lib/python3.6/site-packages/django/template/loader.py", line 61, in render_to_string
    template = get_template(template_name, using=using)
  File "/home/ubuntu/RockJiggu/venv/lib/python3.6/site-packages/django/template/loader.py", line 19, in get_template
    raise TemplateDoesNotExist(template_name, chain=chain)
django.template.exceptions.TemplateDoesNotExist: index.html
[pid: 19556|app: 0|req: 51/51] 110.13.194.132 () {42 vars in 753 bytes} [Thu Oct 24 07:48:05 2019] GET / => generated 69863 bytes in 31 msecs (HTTP/1.1 500) 4 headers in 129 bytes (2 switches on core 0)
Internal Server Error: /
Traceback (most recent call last):
  File "/home/ubuntu/RockJiggu/venv/lib/python3.6/site-packages/django/core/handlers/exception.py", line 34, in inner
    response = get_response(request)
  File "/home/ubuntu/RockJiggu/venv/lib/python3.6/site-packages/django/core/handlers/base.py", line 115, in _get_response
    response = self.process_exception_by_middleware(e, request)
  File "/home/ubuntu/RockJiggu/venv/lib/python3.6/site-packages/django/core/handlers/base.py", line 113, in _get_response
    response = wrapped_callback(request, *callback_args, **callback_kwargs)
  File "./RockJiggu/views.py", line 4, in home
    return render(request, 'index.html')
  File "/home/ubuntu/RockJiggu/venv/lib/python3.6/site-packages/django/shortcuts.py", line 36, in render
    content = loader.render_to_string(template_name, context, request, using=using)
  File "/home/ubuntu/RockJiggu/venv/lib/python3.6/site-packages/django/template/loader.py", line 61, in render_to_string
    template = get_template(template_name, using=using)
  File "/home/ubuntu/RockJiggu/venv/lib/python3.6/site-packages/django/template/loader.py", line 19, in get_template
    raise TemplateDoesNotExist(template_name, chain=chain)
django.template.exceptions.TemplateDoesNotExist: index.html
[pid: 19556|app: 0|req: 52/52] 110.13.194.132 () {42 vars in 753 bytes} [Thu Oct 24 07:50:35 2019] GET / => generated 69863 bytes in 35 msecs (HTTP/1.1 500) 4 headers in 129 bytes (2 switches on core 0)
Internal Server Error: /
Traceback (most recent call last):
  File "/home/ubuntu/RockJiggu/venv/lib/python3.6/site-packages/django/core/handlers/exception.py", line 34, in inner
    response = get_response(request)
  File "/home/ubuntu/RockJiggu/venv/lib/python3.6/site-packages/django/core/handlers/base.py", line 115, in _get_response
    response = self.process_exception_by_middleware(e, request)
  File "/home/ubuntu/RockJiggu/venv/lib/python3.6/site-packages/django/core/handlers/base.py", line 113, in _get_response
    response = wrapped_callback(request, *callback_args, **callback_kwargs)
  File "./RockJiggu/views.py", line 4, in home
    return render(request, 'index.html')
  File "/home/ubuntu/RockJiggu/venv/lib/python3.6/site-packages/django/shortcuts.py", line 36, in render
    content = loader.render_to_string(template_name, context, request, using=using)
  File "/home/ubuntu/RockJiggu/venv/lib/python3.6/site-packages/django/template/loader.py", line 61, in render_to_string
    template = get_template(template_name, using=using)
  File "/home/ubuntu/RockJiggu/venv/lib/python3.6/site-packages/django/template/loader.py", line 19, in get_template
    raise TemplateDoesNotExist(template_name, chain=chain)
django.template.exceptions.TemplateDoesNotExist: index.html
[pid: 19556|app: 0|req: 53/53] 110.13.194.132 () {44 vars in 775 bytes} [Thu Oct 24 08:33:53 2019] GET / => generated 69989 bytes in 40 msecs (HTTP/1.1 500) 4 headers in 129 bytes (2 switches on core 0)
Internal Server Error: /
Traceback (most recent call last):
  File "/home/ubuntu/RockJiggu/venv/lib/python3.6/site-packages/django/core/handlers/exception.py", line 34, in inner
    response = get_response(request)
  File "/home/ubuntu/RockJiggu/venv/lib/python3.6/site-packages/django/core/handlers/base.py", line 115, in _get_response
    response = self.process_exception_by_middleware(e, request)
  File "/home/ubuntu/RockJiggu/venv/lib/python3.6/site-packages/django/core/handlers/base.py", line 113, in _get_response
    response = wrapped_callback(request, *callback_args, **callback_kwargs)
  File "./RockJiggu/views.py", line 4, in home
    return render(request, 'index.html')
  File "/home/ubuntu/RockJiggu/venv/lib/python3.6/site-packages/django/shortcuts.py", line 36, in render
    content = loader.render_to_string(template_name, context, request, using=using)
  File "/home/ubuntu/RockJiggu/venv/lib/python3.6/site-packages/django/template/loader.py", line 61, in render_to_string
    template = get_template(template_name, using=using)
  File "/home/ubuntu/RockJiggu/venv/lib/python3.6/site-packages/django/template/loader.py", line 19, in get_template
    raise TemplateDoesNotExist(template_name, chain=chain)
django.template.exceptions.TemplateDoesNotExist: index.html
[pid: 19556|app: 0|req: 54/54] 110.13.194.132 () {44 vars in 775 bytes} [Thu Oct 24 08:37:17 2019] GET / => generated 69989 bytes in 35 msecs (HTTP/1.1 500) 4 headers in 129 bytes (1 switches on core 0)
Internal Server Error: /
Traceback (most recent call last):
  File "/home/ubuntu/RockJiggu/venv/lib/python3.6/site-packages/django/core/handlers/exception.py", line 34, in inner
    response = get_response(request)
  File "/home/ubuntu/RockJiggu/venv/lib/python3.6/site-packages/django/core/handlers/base.py", line 115, in _get_response
    response = self.process_exception_by_middleware(e, request)
  File "/home/ubuntu/RockJiggu/venv/lib/python3.6/site-packages/django/core/handlers/base.py", line 113, in _get_response
    response = wrapped_callback(request, *callback_args, **callback_kwargs)
  File "./RockJiggu/views.py", line 4, in home
    return render(request, 'index.html')
  File "/home/ubuntu/RockJiggu/venv/lib/python3.6/site-packages/django/shortcuts.py", line 36, in render
    content = loader.render_to_string(template_name, context, request, using=using)
  File "/home/ubuntu/RockJiggu/venv/lib/python3.6/site-packages/django/template/loader.py", line 61, in render_to_string
    template = get_template(template_name, using=using)
  File "/home/ubuntu/RockJiggu/venv/lib/python3.6/site-packages/django/template/loader.py", line 19, in get_template
    raise TemplateDoesNotExist(template_name, chain=chain)
django.template.exceptions.TemplateDoesNotExist: index.html
[pid: 19556|app: 0|req: 55/55] 110.13.194.132 () {44 vars in 775 bytes} [Thu Oct 24 08:39:07 2019] GET / => generated 69989 bytes in 35 msecs (HTTP/1.1 500) 4 headers in 129 bytes (1 switches on core 0)
Internal Server Error: /
Traceback (most recent call last):
  File "/home/ubuntu/RockJiggu/venv/lib/python3.6/site-packages/django/core/handlers/exception.py", line 34, in inner
    response = get_response(request)
  File "/home/ubuntu/RockJiggu/venv/lib/python3.6/site-packages/django/core/handlers/base.py", line 115, in _get_response
    response = self.process_exception_by_middleware(e, request)
  File "/home/ubuntu/RockJiggu/venv/lib/python3.6/site-packages/django/core/handlers/base.py", line 113, in _get_response
    response = wrapped_callback(request, *callback_args, **callback_kwargs)
  File "./RockJiggu/views.py", line 4, in home
    return render(request, 'index.html')
  File "/home/ubuntu/RockJiggu/venv/lib/python3.6/site-packages/django/shortcuts.py", line 36, in render
    content = loader.render_to_string(template_name, context, request, using=using)
  File "/home/ubuntu/RockJiggu/venv/lib/python3.6/site-packages/django/template/loader.py", line 61, in render_to_string
    template = get_template(template_name, using=using)
  File "/home/ubuntu/RockJiggu/venv/lib/python3.6/site-packages/django/template/loader.py", line 19, in get_template
    raise TemplateDoesNotExist(template_name, chain=chain)
django.template.exceptions.TemplateDoesNotExist: index.html
[pid: 19556|app: 0|req: 56/56] 201.49.238.183 () {32 vars in 445 bytes} [Thu Oct 24 09:51:43 2019] GET / => generated 69041 bytes in 38 msecs (HTTP/1.1 500) 4 headers in 129 bytes (2 switches on core 0)
Internal Server Error: /
Traceback (most recent call last):
  File "/home/ubuntu/RockJiggu/venv/lib/python3.6/site-packages/django/core/handlers/exception.py", line 34, in inner
    response = get_response(request)
  File "/home/ubuntu/RockJiggu/venv/lib/python3.6/site-packages/django/core/handlers/base.py", line 115, in _get_response
    response = self.process_exception_by_middleware(e, request)
  File "/home/ubuntu/RockJiggu/venv/lib/python3.6/site-packages/django/core/handlers/base.py", line 113, in _get_response
    response = wrapped_callback(request, *callback_args, **callback_kwargs)
  File "./RockJiggu/views.py", line 4, in home
    return render(request, 'index.html')
  File "/home/ubuntu/RockJiggu/venv/lib/python3.6/site-packages/django/shortcuts.py", line 36, in render
    content = loader.render_to_string(template_name, context, request, using=using)
  File "/home/ubuntu/RockJiggu/venv/lib/python3.6/site-packages/django/template/loader.py", line 61, in render_to_string
    template = get_template(template_name, using=using)
  File "/home/ubuntu/RockJiggu/venv/lib/python3.6/site-packages/django/template/loader.py", line 19, in get_template
    raise TemplateDoesNotExist(template_name, chain=chain)
django.template.exceptions.TemplateDoesNotExist: index.html
[pid: 19556|app: 0|req: 57/57] 212.42.113.250 () {32 vars in 446 bytes} [Thu Oct 24 10:20:10 2019] GET / => generated 69042 bytes in 36 msecs (HTTP/1.1 500) 4 headers in 129 bytes (2 switches on core 0)
Internal Server Error: /
Traceback (most recent call last):
  File "/home/ubuntu/RockJiggu/venv/lib/python3.6/site-packages/django/core/handlers/exception.py", line 34, in inner
    response = get_response(request)
  File "/home/ubuntu/RockJiggu/venv/lib/python3.6/site-packages/django/core/handlers/base.py", line 115, in _get_response
    response = self.process_exception_by_middleware(e, request)
  File "/home/ubuntu/RockJiggu/venv/lib/python3.6/site-packages/django/core/handlers/base.py", line 113, in _get_response
    response = wrapped_callback(request, *callback_args, **callback_kwargs)
  File "./RockJiggu/views.py", line 4, in home
    return render(request, 'index.html')
  File "/home/ubuntu/RockJiggu/venv/lib/python3.6/site-packages/django/shortcuts.py", line 36, in render
    content = loader.render_to_string(template_name, context, request, using=using)
  File "/home/ubuntu/RockJiggu/venv/lib/python3.6/site-packages/django/template/loader.py", line 61, in render_to_string
    template = get_template(template_name, using=using)
  File "/home/ubuntu/RockJiggu/venv/lib/python3.6/site-packages/django/template/loader.py", line 19, in get_template
    raise TemplateDoesNotExist(template_name, chain=chain)
django.template.exceptions.TemplateDoesNotExist: index.html
[pid: 19556|app: 0|req: 58/58] 103.111.52.82 () {32 vars in 444 bytes} [Thu Oct 24 10:39:34 2019] GET / => generated 69040 bytes in 35 msecs (HTTP/1.1 500) 4 headers in 129 bytes (2 switches on core 0)
Internal Server Error: /
Traceback (most recent call last):
  File "/home/ubuntu/RockJiggu/venv/lib/python3.6/site-packages/django/core/handlers/exception.py", line 34, in inner
    response = get_response(request)
  File "/home/ubuntu/RockJiggu/venv/lib/python3.6/site-packages/django/core/handlers/base.py", line 115, in _get_response
    response = self.process_exception_by_middleware(e, request)
  File "/home/ubuntu/RockJiggu/venv/lib/python3.6/site-packages/django/core/handlers/base.py", line 113, in _get_response
    response = wrapped_callback(request, *callback_args, **callback_kwargs)
  File "./RockJiggu/views.py", line 4, in home
    return render(request, 'index.html')
  File "/home/ubuntu/RockJiggu/venv/lib/python3.6/site-packages/django/shortcuts.py", line 36, in render
    content = loader.render_to_string(template_name, context, request, using=using)
  File "/home/ubuntu/RockJiggu/venv/lib/python3.6/site-packages/django/template/loader.py", line 61, in render_to_string
    template = get_template(template_name, using=using)
  File "/home/ubuntu/RockJiggu/venv/lib/python3.6/site-packages/django/template/loader.py", line 19, in get_template
    raise TemplateDoesNotExist(template_name, chain=chain)
django.template.exceptions.TemplateDoesNotExist: index.html
[pid: 19556|app: 0|req: 59/59] 189.39.119.150 () {32 vars in 452 bytes} [Thu Oct 24 12:39:48 2019] GET / => generated 69048 bytes in 35 msecs (HTTP/1.1 500) 4 headers in 129 bytes (2 switches on core 0)
Internal Server Error: /
Traceback (most recent call last):
  File "/home/ubuntu/RockJiggu/venv/lib/python3.6/site-packages/django/core/handlers/exception.py", line 34, in inner
    response = get_response(request)
  File "/home/ubuntu/RockJiggu/venv/lib/python3.6/site-packages/django/core/handlers/base.py", line 115, in _get_response
    response = self.process_exception_by_middleware(e, request)
  File "/home/ubuntu/RockJiggu/venv/lib/python3.6/site-packages/django/core/handlers/base.py", line 113, in _get_response
    response = wrapped_callback(request, *callback_args, **callback_kwargs)
  File "./RockJiggu/views.py", line 4, in home
    return render(request, 'index.html')
  File "/home/ubuntu/RockJiggu/venv/lib/python3.6/site-packages/django/shortcuts.py", line 36, in render
    content = loader.render_to_string(template_name, context, request, using=using)
  File "/home/ubuntu/RockJiggu/venv/lib/python3.6/site-packages/django/template/loader.py", line 61, in render_to_string
    template = get_template(template_name, using=using)
  File "/home/ubuntu/RockJiggu/venv/lib/python3.6/site-packages/django/template/loader.py", line 19, in get_template
    raise TemplateDoesNotExist(template_name, chain=chain)
django.template.exceptions.TemplateDoesNotExist: index.html
[pid: 19556|app: 0|req: 60/60] 110.13.194.132 () {42 vars in 746 bytes} [Thu Oct 24 12:45:20 2019] GET / => generated 69856 bytes in 34 msecs (HTTP/1.1 500) 4 headers in 129 bytes (2 switches on core 0)
Internal Server Error: /
Traceback (most recent call last):
  File "/home/ubuntu/RockJiggu/venv/lib/python3.6/site-packages/django/core/handlers/exception.py", line 34, in inner
    response = get_response(request)
  File "/home/ubuntu/RockJiggu/venv/lib/python3.6/site-packages/django/core/handlers/base.py", line 115, in _get_response
    response = self.process_exception_by_middleware(e, request)
  File "/home/ubuntu/RockJiggu/venv/lib/python3.6/site-packages/django/core/handlers/base.py", line 113, in _get_response
    response = wrapped_callback(request, *callback_args, **callback_kwargs)
  File "./RockJiggu/views.py", line 4, in home
    return render(request, 'index.html')
  File "/home/ubuntu/RockJiggu/venv/lib/python3.6/site-packages/django/shortcuts.py", line 36, in render
    content = loader.render_to_string(template_name, context, request, using=using)
  File "/home/ubuntu/RockJiggu/venv/lib/python3.6/site-packages/django/template/loader.py", line 61, in render_to_string
    template = get_template(template_name, using=using)
  File "/home/ubuntu/RockJiggu/venv/lib/python3.6/site-packages/django/template/loader.py", line 19, in get_template
    raise TemplateDoesNotExist(template_name, chain=chain)
django.template.exceptions.TemplateDoesNotExist: index.html
[pid: 19556|app: 0|req: 61/61] 110.13.194.132 () {42 vars in 746 bytes} [Thu Oct 24 12:59:57 2019] GET / => generated 69856 bytes in 34 msecs (HTTP/1.1 500) 4 headers in 129 bytes (2 switches on core 0)
Internal Server Error: /
Traceback (most recent call last):
  File "/home/ubuntu/RockJiggu/venv/lib/python3.6/site-packages/django/core/handlers/exception.py", line 34, in inner
    response = get_response(request)
  File "/home/ubuntu/RockJiggu/venv/lib/python3.6/site-packages/django/core/handlers/base.py", line 115, in _get_response
    response = self.process_exception_by_middleware(e, request)
  File "/home/ubuntu/RockJiggu/venv/lib/python3.6/site-packages/django/core/handlers/base.py", line 113, in _get_response
    response = wrapped_callback(request, *callback_args, **callback_kwargs)
  File "./RockJiggu/views.py", line 4, in home
    return render(request, 'index.html')
  File "/home/ubuntu/RockJiggu/venv/lib/python3.6/site-packages/django/shortcuts.py", line 36, in render
    content = loader.render_to_string(template_name, context, request, using=using)
  File "/home/ubuntu/RockJiggu/venv/lib/python3.6/site-packages/django/template/loader.py", line 61, in render_to_string
    template = get_template(template_name, using=using)
  File "/home/ubuntu/RockJiggu/venv/lib/python3.6/site-packages/django/template/loader.py", line 19, in get_template
    raise TemplateDoesNotExist(template_name, chain=chain)
django.template.exceptions.TemplateDoesNotExist: index.html
[pid: 19556|app: 0|req: 62/62] 110.13.194.132 () {42 vars in 753 bytes} [Thu Oct 24 13:03:57 2019] GET / => generated 69863 bytes in 38 msecs (HTTP/1.1 500) 4 headers in 129 bytes (2 switches on core 0)
Internal Server Error: /
Traceback (most recent call last):
  File "/home/ubuntu/RockJiggu/venv/lib/python3.6/site-packages/django/core/handlers/exception.py", line 34, in inner
    response = get_response(request)
  File "/home/ubuntu/RockJiggu/venv/lib/python3.6/site-packages/django/core/handlers/base.py", line 115, in _get_response
    response = self.process_exception_by_middleware(e, request)
  File "/home/ubuntu/RockJiggu/venv/lib/python3.6/site-packages/django/core/handlers/base.py", line 113, in _get_response
    response = wrapped_callback(request, *callback_args, **callback_kwargs)
  File "./RockJiggu/views.py", line 4, in home
    return render(request, 'index.html')
  File "/home/ubuntu/RockJiggu/venv/lib/python3.6/site-packages/django/shortcuts.py", line 36, in render
    content = loader.render_to_string(template_name, context, request, using=using)
  File "/home/ubuntu/RockJiggu/venv/lib/python3.6/site-packages/django/template/loader.py", line 61, in render_to_string
    template = get_template(template_name, using=using)
  File "/home/ubuntu/RockJiggu/venv/lib/python3.6/site-packages/django/template/loader.py", line 19, in get_template
    raise TemplateDoesNotExist(template_name, chain=chain)
django.template.exceptions.TemplateDoesNotExist: index.html
[pid: 19556|app: 0|req: 63/63] 110.13.194.132 () {42 vars in 753 bytes} [Thu Oct 24 13:03:58 2019] GET / => generated 69863 bytes in 36 msecs (HTTP/1.1 500) 4 headers in 129 bytes (1 switches on core 0)
Internal Server Error: /
Traceback (most recent call last):
  File "/home/ubuntu/RockJiggu/venv/lib/python3.6/site-packages/django/core/handlers/exception.py", line 34, in inner
    response = get_response(request)
  File "/home/ubuntu/RockJiggu/venv/lib/python3.6/site-packages/django/core/handlers/base.py", line 115, in _get_response
    response = self.process_exception_by_middleware(e, request)
  File "/home/ubuntu/RockJiggu/venv/lib/python3.6/site-packages/django/core/handlers/base.py", line 113, in _get_response
    response = wrapped_callback(request, *callback_args, **callback_kwargs)
  File "./RockJiggu/views.py", line 4, in home
    return render(request, 'index.html')
  File "/home/ubuntu/RockJiggu/venv/lib/python3.6/site-packages/django/shortcuts.py", line 36, in render
    content = loader.render_to_string(template_name, context, request, using=using)
  File "/home/ubuntu/RockJiggu/venv/lib/python3.6/site-packages/django/template/loader.py", line 61, in render_to_string
    template = get_template(template_name, using=using)
  File "/home/ubuntu/RockJiggu/venv/lib/python3.6/site-packages/django/template/loader.py", line 19, in get_template
    raise TemplateDoesNotExist(template_name, chain=chain)
django.template.exceptions.TemplateDoesNotExist: index.html
[pid: 19556|app: 0|req: 64/64] 110.13.194.132 () {42 vars in 753 bytes} [Thu Oct 24 13:03:59 2019] GET / => generated 69863 bytes in 35 msecs (HTTP/1.1 500) 4 headers in 129 bytes (1 switches on core 0)
Internal Server Error: /
Traceback (most recent call last):
  File "/home/ubuntu/RockJiggu/venv/lib/python3.6/site-packages/django/core/handlers/exception.py", line 34, in inner
    response = get_response(request)
  File "/home/ubuntu/RockJiggu/venv/lib/python3.6/site-packages/django/core/handlers/base.py", line 115, in _get_response
    response = self.process_exception_by_middleware(e, request)
  File "/home/ubuntu/RockJiggu/venv/lib/python3.6/site-packages/django/core/handlers/base.py", line 113, in _get_response
    response = wrapped_callback(request, *callback_args, **callback_kwargs)
  File "./RockJiggu/views.py", line 4, in home
    return render(request, 'index.html')
  File "/home/ubuntu/RockJiggu/venv/lib/python3.6/site-packages/django/shortcuts.py", line 36, in render
    content = loader.render_to_string(template_name, context, request, using=using)
  File "/home/ubuntu/RockJiggu/venv/lib/python3.6/site-packages/django/template/loader.py", line 61, in render_to_string
    template = get_template(template_name, using=using)
  File "/home/ubuntu/RockJiggu/venv/lib/python3.6/site-packages/django/template/loader.py", line 19, in get_template
    raise TemplateDoesNotExist(template_name, chain=chain)
django.template.exceptions.TemplateDoesNotExist: index.html
[pid: 19556|app: 0|req: 65/65] 110.13.194.132 () {42 vars in 753 bytes} [Thu Oct 24 13:04:00 2019] GET / => generated 69863 bytes in 31 msecs (HTTP/1.1 500) 4 headers in 129 bytes (1 switches on core 0)
Internal Server Error: /
Traceback (most recent call last):
  File "/home/ubuntu/RockJiggu/venv/lib/python3.6/site-packages/django/core/handlers/exception.py", line 34, in inner
    response = get_response(request)
  File "/home/ubuntu/RockJiggu/venv/lib/python3.6/site-packages/django/core/handlers/base.py", line 115, in _get_response
    response = self.process_exception_by_middleware(e, request)
  File "/home/ubuntu/RockJiggu/venv/lib/python3.6/site-packages/django/core/handlers/base.py", line 113, in _get_response
    response = wrapped_callback(request, *callback_args, **callback_kwargs)
  File "./RockJiggu/views.py", line 4, in home
    return render(request, 'index.html')
  File "/home/ubuntu/RockJiggu/venv/lib/python3.6/site-packages/django/shortcuts.py", line 36, in render
    content = loader.render_to_string(template_name, context, request, using=using)
  File "/home/ubuntu/RockJiggu/venv/lib/python3.6/site-packages/django/template/loader.py", line 61, in render_to_string
    template = get_template(template_name, using=using)
  File "/home/ubuntu/RockJiggu/venv/lib/python3.6/site-packages/django/template/loader.py", line 19, in get_template
    raise TemplateDoesNotExist(template_name, chain=chain)
django.template.exceptions.TemplateDoesNotExist: index.html
[pid: 19556|app: 0|req: 66/66] 110.13.194.132 () {42 vars in 753 bytes} [Thu Oct 24 13:04:00 2019] GET / => generated 69863 bytes in 33 msecs (HTTP/1.1 500) 4 headers in 129 bytes (1 switches on core 0)
Internal Server Error: /
Traceback (most recent call last):
  File "/home/ubuntu/RockJiggu/venv/lib/python3.6/site-packages/django/core/handlers/exception.py", line 34, in inner
    response = get_response(request)
  File "/home/ubuntu/RockJiggu/venv/lib/python3.6/site-packages/django/core/handlers/base.py", line 115, in _get_response
    response = self.process_exception_by_middleware(e, request)
  File "/home/ubuntu/RockJiggu/venv/lib/python3.6/site-packages/django/core/handlers/base.py", line 113, in _get_response
    response = wrapped_callback(request, *callback_args, **callback_kwargs)
  File "./RockJiggu/views.py", line 4, in home
    return render(request, 'index.html')
  File "/home/ubuntu/RockJiggu/venv/lib/python3.6/site-packages/django/shortcuts.py", line 36, in render
    content = loader.render_to_string(template_name, context, request, using=using)
  File "/home/ubuntu/RockJiggu/venv/lib/python3.6/site-packages/django/template/loader.py", line 61, in render_to_string
    template = get_template(template_name, using=using)
  File "/home/ubuntu/RockJiggu/venv/lib/python3.6/site-packages/django/template/loader.py", line 19, in get_template
    raise TemplateDoesNotExist(template_name, chain=chain)
django.template.exceptions.TemplateDoesNotExist: index.html
[pid: 19556|app: 0|req: 67/67] 110.13.194.132 () {42 vars in 753 bytes} [Thu Oct 24 13:04:01 2019] GET / => generated 69863 bytes in 33 msecs (HTTP/1.1 500) 4 headers in 129 bytes (1 switches on core 0)
*** Starting uWSGI 2.0.18 (64bit) on [Thu Oct 24 13:16:28 2019] ***
compiled with version: 7.4.0 on 23 October 2019 07:53:54
os: Linux-4.15.0-1051-aws #53-Ubuntu SMP Wed Sep 18 13:35:53 UTC 2019
nodename: ip-172-31-33-157
machine: x86_64
clock source: unix
detected number of CPU cores: 1
current working directory: /home/ubuntu/RockJiggu
writing pidfile to /tmp/project-master.pid
detected binary path: /home/ubuntu/RockJiggu/venv/bin/uwsgi
!!! no internal routing support, rebuild with pcre support !!!
chdir() to /home/ubuntu/RockJiggu
your processes number limit is 3841
your memory page size is 4096 bytes
detected max file descriptor number: 1024
lock engine: pthread robust mutexes
thunder lock: disabled (you can enable it with --thunder-lock)
uwsgi socket 0 bound to UNIX address /home/ubuntu/RockJiggu/uwsgi.sock fd 3
Python version: 3.6.8 (default, Oct  7 2019, 12:59:55)  [GCC 8.3.0]
Set PythonHome to /home/ubuntu/RockJiggu/venv
*** Python threads support is disabled. You can enable it with --enable-threads ***
Python main interpreter initialized at 0x560368057690
your server socket listen backlog is limited to 100 connections
your mercy for graceful operations on workers is 60 seconds
mapped 145808 bytes (142 KB) for 1 cores
*** Operational MODE: single process ***
WSGI app 0 (mountpoint='') ready in 0 seconds on interpreter 0x560368057690 pid: 32734 (default app)
*** uWSGI is running in multiple interpreter mode ***
spawned uWSGI master process (pid: 32734)
spawned uWSGI worker 1 (pid: 32736, cores: 1)
[pid: 32736|app: 0|req: 1/1] 110.13.194.132 () {44 vars in 775 bytes} [Thu Oct 24 13:16:42 2019] GET / => generated 12918 bytes in 33 msecs (HTTP/1.1 200) 3 headers in 111 bytes (2 switches on core 0)
[pid: 32736|app: 0|req: 2/2] 211.231.103.94 () {38 vars in 563 bytes} [Thu Oct 24 13:29:53 2019] GET / => generated 12918 bytes in 6 msecs (HTTP/1.1 200) 3 headers in 111 bytes (2 switches on core 0)
[pid: 32736|app: 0|req: 3/3] 14.42.51.80 () {40 vars in 749 bytes} [Thu Oct 24 13:31:54 2019] GET / => generated 12918 bytes in 5 msecs (HTTP/1.1 200) 3 headers in 111 bytes (1 switches on core 0)
Internal Server Error: /webhook/
Traceback (most recent call last):
  File "/home/ubuntu/RockJiggu/venv/lib/python3.6/site-packages/django/core/handlers/exception.py", line 34, in inner
    response = get_response(request)
  File "/home/ubuntu/RockJiggu/venv/lib/python3.6/site-packages/django/core/handlers/base.py", line 126, in _get_response
    "returned None instead." % (callback.__module__, view_name)
ValueError: The view chatbot.views.webhook didn't return an HttpResponse object. It returned None instead.
[pid: 32736|app: 0|req: 4/4] 14.42.51.80 () {42 vars in 803 bytes} [Thu Oct 24 13:32:00 2019] GET /webhook/ => generated 48803 bytes in 49 msecs (HTTP/1.1 500) 4 headers in 129 bytes (2 switches on core 0)
Not Found: /favicon.ico
[pid: 32736|app: 0|req: 5/5] 14.42.51.80 () {40 vars in 703 bytes} [Thu Oct 24 13:32:00 2019] GET /favicon.ico => generated 2196 bytes in 2 msecs (HTTP/1.1 404) 3 headers in 102 bytes (1 switches on core 0)
Not Found: /index.html
[pid: 32736|app: 0|req: 6/6] 14.42.51.80 () {42 vars in 807 bytes} [Thu Oct 24 13:36:10 2019] GET /index.html => generated 2193 bytes in 3 msecs (HTTP/1.1 404) 3 headers in 102 bytes (1 switches on core 0)
Not Found: /home-carousel.html
[pid: 32736|app: 0|req: 7/7] 14.42.51.80 () {42 vars in 823 bytes} [Thu Oct 24 13:36:13 2019] GET /home-carousel.html => generated 2217 bytes in 3 msecs (HTTP/1.1 404) 3 headers in 102 bytes (1 switches on core 0)
Not Found: /compare.html
[pid: 32736|app: 0|req: 8/8] 14.42.51.80 () {42 vars in 811 bytes} [Thu Oct 24 13:36:16 2019] GET /compare.html => generated 2199 bytes in 3 msecs (HTTP/1.1 404) 3 headers in 102 bytes (1 switches on core 0)
[pid: 32736|app: 0|req: 9/9] 110.13.194.132 () {44 vars in 789 bytes} [Thu Oct 24 14:01:22 2019] GET /webhook => generated 0 bytes in 1 msecs (HTTP/1.1 301) 3 headers in 114 bytes (1 switches on core 0)
Internal Server Error: /webhook/
Traceback (most recent call last):
  File "/home/ubuntu/RockJiggu/venv/lib/python3.6/site-packages/django/core/handlers/exception.py", line 34, in inner
    response = get_response(request)
  File "/home/ubuntu/RockJiggu/venv/lib/python3.6/site-packages/django/core/handlers/base.py", line 126, in _get_response
    "returned None instead." % (callback.__module__, view_name)
ValueError: The view chatbot.views.webhook didn't return an HttpResponse object. It returned None instead.
[pid: 32736|app: 0|req: 10/10] 110.13.194.132 () {44 vars in 791 bytes} [Thu Oct 24 14:01:22 2019] GET /webhook/ => generated 48895 bytes in 28 msecs (HTTP/1.1 500) 4 headers in 129 bytes (1 switches on core 0)
